Workbook
Name adat25: [1]S25A60_feld!$A$1:$O$113
Name adatok: [2]S15A60_feld!$A$1:$O$127
Name alap_fny: [3]vizsgálat!$U$3:$U$1222
Name alap_vtg: [3]vizsgálat!$V$3:$V$1222
Name aszfalt_vtg: [3]vizsgálat!$AM$3:$AM$1222
Name átk_érték: [3]új!$M$3:$M$31
Name átk_kmsz: [3]új!$L$3:$L$31
Name beh_kmsz: [3]új!$E$3:$E$32
Name behajlás: [3]új!$F$3:$F$32
Name beton_kmsz: [3]utolsó!$Q$3:$Q$20
Name beton_vtg: [3]utolsó!$S$3:$S$20
Name burk_áll: [3]új!$I$3:$I$40
Name burkolatszélesség: [3]utolsó!$V$3:$V$244
Name burkszél_kmsz: [3]utolsó!$U$3:$U$244
Name ero: [4]MET!$E$9
Name erősítő_kmsz: [3]utolsó!$G$3:$G$94
Name erősítő_vtg: [3]utolsó!$H$3:$H$94
Name fajlagos_nyommélység: [3]vizsgálat!$AF$3:$AF$1222
Name felületépség: [5]vizsgálat!$AM$3:$AM$1222
Name határ: [3]adatok!$B$19
Name képlet: [3]új!$S$1:$T$1
Name kezd: [3]adatok!$B$17
Name kmsz: [3]vizsgálat!$T$3:$T$1222
Name kmsz_hely: [3]vizsgálat!$AA$3:$AA$1222
Name kopó_fny: [3]vizsgálat!$Y$3:$Y$1222
Name kopó_vtg: [3]vizsgálat!$Z$3:$Z$1222
Name korr_f1: [4]MET!$I$23
Name korr_f2: [4]MET!$I$24
Name kötő_fny: [3]vizsgálat!$W$3:$W$1222
Name kötő_vtg: [3]vizsgálat!$X$3:$X$1222
Name lista: #REF!
Name lreom: #REF!
Name marás_kmsz: [3]utolsó!$D$3:$D$21
Name marás_vtg: [3]utolsó!$E$3:$E$21
Name maximum: [3]adatok!$D$4
Name mért_kmsz: [3]mérés!$A$2:$A$4825
Name mért_nym: [3]mérés!$B$2:$B$4825
Name minimum: [3]adatok!$D$3
Name mod_e1: [4]MET!$E$16
Name mod_e2: [4]MET!$E$17
Name mod_e3: [4]MET!$E$18
Name OKA_burk: [3]még!$B$2:$B$232
Name OKA_kmsz: [3]még!$A$2:$A$232
Name OKA_vízt: [3]még!$C$2:$C$232
Name pdb: #REF!
Name poisson_v1: [4]MET!$M$16
Name poisson_v2: [4]MET!$M$17
Name poisson_v3: [4]MET!$M$18
Name pontok: [3]vizsgálat!$AI$3
Name rdb: #REF!
Name rétegvastagság: [3]vizsgálat!$AG$3:$AG$1222
Name rm_kmsz: [3]új!$H$3:$H$40
Name rvtg_h1: [4]MET!$I$16
Name rvtg_h2: [4]MET!$I$17
Name skála: [3]vizsgálat!$J$3:$J$1222
Name sugar: [4]MET!$E$8
Name szakasz: [3]vizsgálat!$B$3:$B$81
Name szeg_b2: [3]új!$S$3:$S$270
Name szeg_bal: [3]új!$Q$3:$Q$270
Name szeg_j2: [3]új!$T$3:$T$270

Sheet paraméter számoló (2)
B1: 0 | C1: 200 | D1: 300 | E1: 450 | F1: 600 | G1: 900 | H1: 1200 | I1: 0 | J1: =LOG10(C1) -> 2.30103 | K1: =LOG10(D1) -> 2.4771213 | L1: =LOG10(E1) -> 2.6532125 | M1: =LOG10(F1) -> 2.7781513 | N1: =LOG10(G1) -> 2.9542425 | O1: =LOG10(H1) -> 3.0791812
B2: D1 | C2: D2 | D2: D3 | E2: D4 | F2: D5 | G2: D6 | H2: D7 | I2: D1 | J2: D2 | K2: D3 | L2: D4 | M2: D5 | N2: D6 | O2: D7 | P2: α | Q2: β | R2: c | S2: R0 (m) | T2: R1 (m) | U2: L (mm) | V2: T (mm2) | W2: l | Y2: SCI | Z2: BDI | AA2: BCI | AC2: D1 | AD2: D2 | AE2: D3 | AF2: D4 | AG2: D5 | AH2: D6 | AI2: D7
B3: 0 | C3: 200 | D3: 300 | E3: 450 | F3: 600 | G3: 900 | H3: 1200 | AC3: 0 | AD3: 200 | AE3: 300 | AF3: 450 | AG3: 600 | AH3: 900 | AI3: 1200
A4: 378 | B4: 213.8 | C4: 186.4 | D4: 167.8 | E4: 136.2 | F4: 115.7 | G4: 72.7 | H4: 45.2 | I4: =B4/1000 -> 0.2138 | J4: =LOG10((((3*150*150)*B4)/C4)-((3*150*150))) -> 3.9966084 | K4: =LOG10((((3*150*150)*B4)/D4)-((3*150*150))) -> 4.2672696 | L4: =LOG10((((3*150*150)*B4)/E4)-((3*150*150))) -> 4.5849884 | M4: =LOG10((((3*150*150)*B4)/F4)-((3*150*150))) -> 4.7576394 | N4: =LOG10((((3*150*150)*B4)/G4)-((3*150*150))) -> 5.1172964 | O4: =LOG10((((3*150*150)*B4)/H4)-((3*150*150))) -> 5.4010229 | P4: =10^(INTERCEPT(J4:O4,$J$1:$O$1)) -> 0.71307304 | Q4: =LINEST(J4:O4,$J$1:$O$1) -> 1.7857619 | R4: =ROUND(10^((SUM(J4:N4)-2*SUM($J$1:$N$1))/5),3) -> 0.19 | S4: =ROUND(-1.5*((150^2)/(R4*I4))/1000,0) -> -831 | T4: =-4*S4 -> 3324 | U4: =ROUND(150/(R4^0.5),0) -> 344 | V4: =ROUND(150*I4*ATAN((1800*SQRT(3*R4))/(3*150))*SQRT(3/(R4)),0) -> 159 | W4: =ROUND(1/SQRT(R4),3) -> 2.294 | Y4: =ROUND(B4-D4,3) -> 46 | Z4: =ROUND(D4-F4,3) -> 52.1 | AA4: =ROUND(F4-G4,3) -> 43 | AC4: =((B4)*3*150^2)/(R4*$AC$3^2+3*150^2) -> 213.8 | AD4: =((B4)*3*150^2)/(R4*$AD$3^2+3*150^2) -> 192.16378 | AE4: =((B4)*3*150^2)/(R4*$AE$3^2+3*150^2) -> 170.58511 | AF4: =((B4)*3*150^2)/(R4*$AF$3^2+3*150^2) -> 136.17834 | AG4: =((B4)*3*150^2)/(R4*$AG$3^2+3*150^2) -> 106.19205 | AH4: =((B4)*3*150^2)/(R4*$AH$3^2+3*150^2) -> 65.182927 | AI4: =((B4)*3*150^2)/(R4*$AI$3^2+3*150^2) -> 42.308707 | AJ4: =ROUND((-0.07/(2*S4))*1000000,0) -> 42
A5: 380 | B5: 201.6 | C5: 175.2 | D5: 156.7 | E5: 127.5 | F5: 108.1 | G5: 68.1 | H5: 41.6 | I5: =B5/1000 -> 0.2016 | J5: =LOG10((((3*150*150)*B5)/C5)-((3*150*150))) -> 4.0073736 | K5: =LOG10((((3*150*150)*B5)/D5)-((3*150*150))) -> 4.2864811 | L5: =LOG10((((3*150*150)*B5)/E5)-((3*150*150))) -> 4.5936118 | M5: =LOG10((((3*150*150)*B5)/F5)-((3*150*150))) -> 4.7662897 | N5: =LOG10((((3*150*150)*B5)/G5)-((3*150*150))) -> 5.1216379 | O5: =LOG10((((3*150*150)*B5)/H5)-((3*150*150))) -> 5.4143304 | P5: =10^(INTERCEPT(J5:O5,$J$1:$O$1)) -> 0.75966553 | Q5: =LINEST(J5:O5,$J$1:$O$1) -> 1.7796035 | R5: =ROUND(10^((SUM(J5:N5)-2*SUM($J$1:$N$1))/5),3) -> 0.195 | S5: =ROUND(-1.5*((150^2)/(R5*I5))/1000,0) -> -859 | T5: =-4*S5 -> 3436 | U5: =ROUND(150/(R5^0.5),0) -> 340 | V5: =ROUND(150*I5*ATAN((1800*SQRT(3*R5))/(3*150))*SQRT(3/(R5)),0) -> 149 | W5: =ROUND(1/SQRT(R5),3) -> 2.265 | Y5: =ROUND(B5-D5,3) -> 44.9 | Z5: =ROUND(D5-F5,3) -> 48.6 | AA5: =ROUND(F5-G5,3) -> 40 | AC5: =((B5)*3*150^2)/(R5*$AC$3^2+3*150^2) -> 201.6 | AD5: =((B5)*3*150^2)/(R5*$AD$3^2+3*150^2) -> 180.71713 | AE5: =((B5)*3*150^2)/(R5*$AE$3^2+3*150^2) -> 160 | AF5: =((B5)*3*150^2)/(R5*$AF$3^2+3*150^2) -> 127.19243 | AG5: =((B5)*3*150^2)/(R5*$AG$3^2+3*150^2) -> 98.823529 | AH5: =((B5)*3*150^2)/(R5*$AH$3^2+3*150^2) -> 60.359281 | AI5: =((B5)*3*150^2)/(R5*$AI$3^2+3*150^2) -> 39.069767 | AJ5: =ROUND((-0.07/(2*S5))*1000000,0) -> 41
A6: 383 | B6: 199.6 | C6: 173.1 | D6: 155 | E6: 125.7 | F6: 107.1 | G6: 67.1 | H6: 40.8 | I6: =B6/1000 -> 0.1996 | J6: =LOG10((((3*150*150)*B6)/C6)-((3*150*150))) -> 4.0142526 | K6: =LOG10((((3*150*150)*B6)/D6)-((3*150*150))) -> 4.2883069 | L6: =LOG10((((3*150*150)*B6)/E6)-((3*150*150))) -> 4.5986129 | M6: =LOG10((((3*150*150)*B6)/F6)-((3*150*150))) -> 4.765656 | N6: =LOG10((((3*150*150)*B6)/G6)-((3*150*150))) -> 5.1247971 | O6: =LOG10((((3*150*150)*B6)/H6)-((3*150*150))) -> 5.4194941 | P6: =10^(INTERCEPT(J6:O6,$J$1:$O$1)) -> 0.7752686 | Q6: =LINEST(J6:O6,$J$1:$O$1) -> 1.777659 | R6: =ROUND(10^((SUM(J6:N6)-2*SUM($J$1:$N$1))/5),3) -> 0.196 | S6: =ROUND(-1.5*((150^2)/(R6*I6))/1000,0) -> -863 | T6: =-4*S6 -> 3452 | U6: =ROUND(150/(R6^0.5),0) -> 339 | V6: =ROUND(150*I6*ATAN((1800*SQRT(3*R6))/(3*150))*SQRT(3/(R6)),0) -> 147 | W6: =ROUND(1/SQRT(R6),3) -> 2.259 | Y6: =ROUND(B6-D6,3) -> 44.6 | Z6: =ROUND(D6-F6,3) -> 47.9 | AA6: =ROUND(F6-G6,3) -> 40 | AC6: =((B6)*3*150^2)/(R6*$AC$3^2+3*150^2) -> 199.6 | AD6: =((B6)*3*150^2)/(R6*$AD$3^2+3*150^2) -> 178.82931 | AE6: =((B6)*3*150^2)/(R6*$AE$3^2+3*150^2) -> 158.24524 | AF6: =((B6)*3*150^2)/(R6*$AF$3^2+3*150^2) -> 125.6927 | AG6: =((B6)*3*150^2)/(R6*$AG$3^2+3*150^2) -> 97.588005 | AH6: =((B6)*3*150^2)/(R6*$AH$3^2+3*150^2) -> 59.546539 | AI6: =((B6)*3*150^2)/(R6*$AI$3^2+3*150^2) -> 38.522903 | AJ6: =ROUND((-0.07/(2*S6))*1000000,0) -> 41
A7: 383 | B7: 197.5 | C7: 171.5 | D7: 153.7 | E7: 125 | F7: 106.7 | G7: 67 | H7: 40.8 | I7: =B7/1000 -> 0.1975 | J7: =LOG10((((3*150*150)*B7)/C7)-((3*150*150))) -> 4.010013 | K7: =LOG10((((3*150*150)*B7)/D7)-((3*150*150))) -> 4.284104 | L7: =LOG10((((3*150*150)*B7)/E7)-((3*150*150))) -> 4.5927318 | M7: =LOG10((((3*150*150)*B7)/F7)-((3*150*150))) -> 4.7592252 | N7: =LOG10((((3*150*150)*B7)/G7)-((3*150*150))) -> 5.1188395 | O7: =LOG10((((3*150*150)*B7)/H7)-((3*150*150))) -> 5.4137126 | P7: =10^(INTERCEPT(J7:O7,$J$1:$O$1)) -> 0.7778054 | Q7: =LINEST(J7:O7,$J$1:$O$1) -> 1.7751345 | R7: =ROUND(10^((SUM(J7:N7)-2*SUM($J$1:$N$1))/5),3) -> 0.194 | S7: =ROUND(-1.5*((150^2)/(R7*I7))/1000,0) -> -881 | T7: =-4*S7 -> 3524 | U7: =ROUND(150/(R7^0.5),0) -> 341 | V7: =ROUND(150*I7*ATAN((1800*SQRT(3*R7))/(3*150))*SQRT(3/(R7)),0) -> 146 | W7: =ROUND(1/SQRT(R7),3) -> 2.27 | Y7: =ROUND(B7-D7,3) -> 43.8 | Z7: =ROUND(D7-F7,3) -> 47 | AA7: =ROUND(F7-G7,3) -> 39.7 | AC7: =((B7)*3*150^2)/(R7*$AC$3^2+3*150^2) -> 197.5 | AD7: =((B7)*3*150^2)/(R7*$AD$3^2+3*150^2) -> 177.13593 | AE7: =((B7)*3*150^2)/(R7*$AE$3^2+3*150^2) -> 156.91208 | AF7: =((B7)*3*150^2)/(R7*$AF$3^2+3*150^2) -> 124.84197 | AG7: =((B7)*3*150^2)/(R7*$AG$3^2+3*150^2) -> 97.067497 | AH7: =((B7)*3*150^2)/(R7*$AH$3^2+3*150^2) -> 59.344952 | AI7: =((B7)*3*150^2)/(R7*$AI$3^2+3*150^2) -> 38.434094 | AJ7: =ROUND((-0.07/(2*S7))*1000000,0) -> 40
A8: 724 | B8: 363 | C8: 319.2 | D8: 287 | E8: 240.5 | F8: 200.4 | G8: 134.5 | H8: 87.7 | I8: =B8/1000 -> 0.363 | J8: =LOG10((((3*150*150)*B8)/C8)-((3*150*150))) -> 3.966715 | K8: =LOG10((((3*150*150)*B8)/D8)-((3*150*150))) -> 4.2522355 | L8: =LOG10((((3*150*150)*B8)/E8)-((3*150*150))) -> 4.5363248 | M8: =LOG10((((3*150*150)*B8)/F8)-((3*150*150))) -> 4.7385266 | N8: =LOG10((((3*150*150)*B8)/G8)-((3*150*150))) -> 5.0594677 | O8: =LOG10((((3*150*150)*B8)/H8)-((3*150*150))) -> 5.3261104 | P8: =10^(INTERCEPT(J8:O8,$J$1:$O$1)) -> 0.94021169 | Q8: =LINEST(J8:O8,$J$1:$O$1) -> 1.7262902 | R8: =ROUND(10^((SUM(J8:N8)-2*SUM($J$1:$N$1))/5),3) -> 0.176 | S8: =ROUND(-1.5*((150^2)/(R8*I8))/1000,0) -> -528 | T8: =-4*S8 -> 2112 | U8: =ROUND(150/(R8^0.5),0) -> 358 | V8: =ROUND(150*I8*ATAN((1800*SQRT(3*R8))/(3*150))*SQRT(3/(R8)),0) -> 279 | W8: =ROUND(1/SQRT(R8),3) -> 2.384 | Y8: =ROUND(B8-D8,3) -> 76 | Z8: =ROUND(D8-F8,3) -> 86.6 | AA8: =ROUND(F8-G8,3) -> 65.9 | AC8: =((B8)*3*150^2)/(R8*$AC$3^2+3*150^2) -> 363 | AD8: =((B8)*3*150^2)/(R8*$AD$3^2+3*150^2) -> 328.71613 | AE8: =((B8)*3*150^2)/(R8*$AE$3^2+3*150^2) -> 294.00648 | AF8: =((B8)*3*150^2)/(R8*$AF$3^2+3*150^2) -> 237.56545 | AG8: =((B8)*3*150^2)/(R8*$AG$3^2+3*150^2) -> 187.24209 | AH8: =((B8)*3*150^2)/(R8*$AH$3^2+3*150^2) -> 116.64524 | AI8: =((B8)*3*150^2)/(R8*$AI$3^2+3*150^2) -> 76.346046 | AJ8: =ROUND((-0.07/(2*S8))*1000000,0) -> 66
A9: 715 | B9: 350.2 | C9: 308 | D9: 276.6 | E9: 231.3 | F9: 194 | G9: 129.7 | H9: 84.6 | I9: =B9/1000 -> 0.3502 | J9: =LOG10((((3*150*150)*B9)/C9)-((3*150*150))) -> 3.9660655 | K9: =LOG10((((3*150*150)*B9)/D9)-((3*150*150))) -> 4.2543294 | L9: =LOG10((((3*150*150)*B9)/E9)-((3*150*150))) -> 4.54031 | M9: =LOG10((((3*150*150)*B9)/F9)-((3*150*150))) -> 4.7351831 | N9: =LOG10((((3*150*150)*B9)/G9)-((3*150*150))) -> 5.0597724 | O9: =LOG10((((3*150*150)*B9)/H9)-((3*150*150))) -> 5.3261615 | P9: =10^(INTERCEPT(J9:O9,$J$1:$O$1)) -> 0.94907197 | Q9: =LINEST(J9:O9,$J$1:$O$1) -> 1.7249358 | R9: =ROUND(10^((SUM(J9:N9)-2*SUM($J$1:$N$1))/5),3) -> 0.176 | S9: =ROUND(-1.5*((150^2)/(R9*I9))/1000,0) -> -548 | T9: =-4*S9 -> 2192 | U9: =ROUND(150/(R9^0.5),0) -> 358 | V9: =ROUND(150*I9*ATAN((1800*SQRT(3*R9))/(3*150))*SQRT(3/(R9)),0) -> 269 | W9: =ROUND(1/SQRT(R9),3) -> 2.384 | Y9: =ROUND(B9-D9,3) -> 73.6 | Z9: =ROUND(D9-F9,3) -> 82.6 | AA9: =ROUND(F9-G9,3) -> 64.3 | AC9: =((B9)*3*150^2)/(R9*$AC$3^2+3*150^2) -> 350.2 | AD9: =((B9)*3*150^2)/(R9*$AD$3^2+3*150^2) -> 317.12503 | AE9: =((B9)*3*150^2)/(R9*$AE$3^2+3*150^2) -> 283.63931 | AF9: =((B9)*3*150^2)/(R9*$AF$3^2+3*150^2) -> 229.18848 | AG9: =((B9)*3*150^2)/(R9*$AG$3^2+3*150^2) -> 180.63961 | AH9: =((B9)*3*150^2)/(R9*$AH$3^2+3*150^2) -> 112.53213 | AI9: =((B9)*3*150^2)/(R9*$AI$3^2+3*150^2) -> 73.653954 | AJ9: =ROUND((-0.07/(2*S9))*1000000,0) -> 64
A10: 712 | B10: 347.3 | C10: 305.6 | D10: 274.6 | E10: 229.3 | F10: 193.1 | G10: 128.9 | H10: 84.6 | I10: =B10/1000 -> 0.3473 | J10: =LOG10((((3*150*150)*B10)/C10)-((3*150*150))) -> 3.9642865 | K10: =LOG10((((3*150*150)*B10)/D10)-((3*150*150))) -> 4.2521377 | L10: =LOG10((((3*150*150)*B10)/E10)-((3*150*150))) -> 4.5407817 | M10: =LOG10((((3*150*150)*B10)/F10)-((3*150*150))) -> 4.7316059 | N10: =LOG10((((3*150*150)*B10)/G10)-((3*150*150))) -> 5.0583035 | O10: =LOG10((((3*150*150)*B10)/H10)-((3*150*150))) -> 5.3213935 | P10: =10^(INTERCEPT(J10:O10,$J$1:$O$1)) -> 0.96084286 | Q10: =LINEST(J10:O10,$J$1:$O$1) -> 1.7221388 | R10: =ROUND(10^((SUM(J10:N10)-2*SUM($J$1:$N$1))/5),3) -> 0.175 | S10: =ROUND(-1.5*((150^2)/(R10*I10))/1000,0) -> -555 | T10: =-4*S10 -> 2220 | U10: =ROUND(150/(R10^0.5),0) -> 359 | V10: =ROUND(150*I10*ATAN((1800*SQRT(3*R10))/(3*150))*SQRT(3/(R10)),0) -> 267 | W10: =ROUND(1/SQRT(R10),3) -> 2.39 | Y10: =ROUND(B10-D10,3) -> 72.7 | Z10: =ROUND(D10-F10,3) -> 81.5 | AA10: =ROUND(F10-G10,3) -> 64.2 | AC10: =((B10)*3*150^2)/(R10*$AC$3^2+3*150^2) -> 347.3 | AD10: =((B10)*3*150^2)/(R10*$AD$3^2+3*150^2) -> 314.66779 | AE10: =((B10)*3*150^2)/(R10*$AE$3^2+3*150^2) -> 281.59459 | AF10: =((B10)*3*150^2)/(R10*$AF$3^2+3*150^2) -> 227.7377 | AG10: =((B10)*3*150^2)/(R10*$AG$3^2+3*150^2) -> 179.63793 | AH10: =((B10)*3*150^2)/(R10*$AH$3^2+3*150^2) -> 112.03226 | AI10: =((B10)*3*150^2)/(R10*$AI$3^2+3*150^2) -> 73.373239 | AJ10: =ROUND((-0.07/(2*S10))*1000000,0) -> 63
A11: 710 | B11: 345.8 | C11: 304.2 | D11: 273 | E11: 227.4 | F11: 192.9 | G11: 127.8 | H11: 83.9 | I11: =B11/1000 -> 0.3458 | J11: =LOG10((((3*150*150)*B11)/C11)-((3*150*150))) -> 3.9652379 | K11: =LOG10((((3*150*150)*B11)/D11)-((3*150*150))) -> 4.2552725 | L11: =LOG10((((3*150*150)*B11)/E11)-((3*150*150))) -> 4.545865 | M11: =LOG10((((3*150*150)*B11)/F11)-((3*150*150))) -> 4.728379 | N11: =LOG10((((3*150*150)*B11)/G11)-((3*150*150))) -> 5.0612294 | O11: =LOG10((((3*150*150)*B11)/H11)-((3*150*150))) -> 5.3236773 | P11: =10^(INTERCEPT(J11:O11,$J$1:$O$1)) -> 0.96550487 | Q11: =LINEST(J11:O11,$J$1:$O$1) -> 1.7220489 | R11: =ROUND(10^((SUM(J11:N11)-2*SUM($J$1:$N$1))/5),3) -> 0.176 | S11: =ROUND(-1.5*((150^2)/(R11*I11))/1000,0) -> -555 | T11: =-4*S11 -> 2220 | U11: =ROUND(150/(R11^0.5),0) -> 358 | V11: =ROUND(150*I11*ATAN((1800*SQRT(3*R11))/(3*150))*SQRT(3/(R11)),0) -> 265 | W11: =ROUND(1/SQRT(R11),3) -> 2.384 | Y11: =ROUND(B11-D11,3) -> 72.8 | Z11: =ROUND(D11-F11,3) -> 80.1 | AA11: =ROUND(F11-G11,3) -> 65.1 | AC11: =((B11)*3*150^2)/(R11*$AC$3^2+3*150^2) -> 345.8 | AD11: =((B11)*3*150^2)/(R11*$AD$3^2+3*150^2) -> 313.1406 | AE11: =((B11)*3*150^2)/(R11*$AE$3^2+3*150^2) -> 280.07559 | AF11: =((B11)*3*150^2)/(R11*$AF$3^2+3*150^2) -> 226.3089 | AG11: =((B11)*3*150^2)/(R11*$AG$3^2+3*150^2) -> 178.37001 | AH11: =((B11)*3*150^2)/(R11*$AH$3^2+3*150^2) -> 111.11825 | AI11: =((B11)*3*150^2)/(R11*$AI$3^2+3*150^2) -> 72.728547 | AJ11: =ROUND((-0.07/(2*S11))*1000000,0) -> 63
A12: 1372 | B12: 584 | C12: 515.7 | D12: 464.1 | E12: 390.3 | F12: 330.2 | G12: 223.2 | H12: 149.4 | I12: =B12/1000 -> 0.584 | J12: =LOG10((((3*150*150)*B12)/C12)-((3*150*150))) -> 3.9513273 | K12: =LOG10((((3*150*150)*B12)/D12)-((3*150*150))) -> 4.2415114 | L12: =LOG10((((3*150*150)*B12)/E12)-((3*150*150))) -> 4.5250348 | M12: =LOG10((((3*150*150)*B12)/F12)-((3*150*150))) -> 4.7150183 | N12: =LOG10((((3*150*150)*B12)/G12)-((3*150*150))) -> 5.0378761 | O12: =LOG10((((3*150*150)*B12)/H12)-((3*150*150))) -> 5.2930429 | P12: =10^(INTERCEPT(J12:O12,$J$1:$O$1)) -> 1.0411172 | Q12: =LINEST(J12:O12,$J$1:$O$1) -> 1.7028208 | R12: =ROUND(10^((SUM(J12:N12)-2*SUM($J$1:$N$1))/5),3) -> 0.169 | S12: =ROUND(-1.5*((150^2)/(R12*I12))/1000,0) -> -342 | T12: =-4*S12 -> 1368 | U12: =ROUND(150/(R12^0.5),0) -> 365 | V12: =ROUND(150*I12*ATAN((1800*SQRT(3*R12))/(3*150))*SQRT(3/(R12)),0) -> 455 | W12: =ROUND(1/SQRT(R12),3) -> 2.433 | Y12: =ROUND(B12-D12,3) -> 119.9 | Z12: =ROUND(D12-F12,3) -> 133.9 | AA12: =ROUND(F12-G12,3) -> 107 | AC12: =((B12)*3*150^2)/(R12*$AC$3^2+3*150^2) -> 584 | AD12: =((B12)*3*150^2)/(R12*$AD$3^2+3*150^2) -> 530.8376 | AE12: =((B12)*3*150^2)/(R12*$AE$3^2+3*150^2) -> 476.60501 | AF12: =((B12)*3*150^2)/(R12*$AF$3^2+3*150^2) -> 387.52488 | AG12: =((B12)*3*150^2)/(R12*$AG$3^2+3*150^2) -> 307.15288 | AH12: =((B12)*3*150^2)/(R12*$AH$3^2+3*150^2) -> 192.86658 | AI12: =((B12)*3*150^2)/(R12*$AI$3^2+3*150^2) -> 126.8095 | AJ12: =ROUND((-0.07/(2*S12))*1000000,0) -> 102
A13: 1407 | B13: 580.3 | C13: 512.7 | D13: 459.6 | E13: 387.3 | F13: 329.9 | G13: 223 | H13: 148.7 | I13: =B13/1000 -> 0.5803 | J13: =LOG10((((3*150*150)*B13)/C13)-((3*150*150))) -> 3.9493872 | K13: =LOG10((((3*150*150)*B13)/D13)-((3*150*150))) -> 4.248631 | L13: =LOG10((((3*150*150)*B13)/E13)-((3*150*150))) -> 4.5268136 | M13: =LOG10((((3*150*150)*B13)/F13)-((3*150*150))) -> 4.7095558 | N13: =LOG10((((3*150*150)*B13)/G13)-((3*150*150))) -> 5.0340319 | O13: =LOG10((((3*150*150)*B13)/H13)-((3*150*150))) -> 5.2920742 | P13: =10^(INTERCEPT(J13:O13,$J$1:$O$1)) -> 1.0808782 | Q13: =LINEST(J13:O13,$J$1:$O$1) -> 1.6966039 | R13: =ROUND(10^((SUM(J13:N13)-2*SUM($J$1:$N$1))/5),3) -> 0.169 | S13: =ROUND(-1.5*((150^2)/(R13*I13))/1000,0) -> -344 | T13: =-4*S13 -> 1376 | U13: =ROUND(150/(R13^0.5),0) -> 365 | V13: =ROUND(150*I13*ATAN((1800*SQRT(3*R13))/(3*150))*SQRT(3/(R13)),0) -> 452 | W13: =ROUND(1/SQRT(R13),3) -> 2.433 | Y13: =ROUND(B13-D13,3) -> 120.7 | Z13: =ROUND(D13-F13,3) -> 129.7 | AA13: =ROUND(F13-G13,3) -> 106.9 | AC13: =((B13)*3*150^2)/(R13*$AC$3^2+3*150^2) -> 580.3 | AD13: =((B13)*3*150^2)/(R13*$AD$3^2+3*150^2) -> 527.47441 | AE13: =((B13)*3*150^2)/(R13*$AE$3^2+3*150^2) -> 473.58542 | AF13: =((B13)*3*150^2)/(R13*$AF$3^2+3*150^2) -> 385.06967 | AG13: =((B13)*3*150^2)/(R13*$AG$3^2+3*150^2) -> 305.20687 | AH13: =((B13)*3*150^2)/(R13*$AH$3^2+3*150^2) -> 191.64465 | AI13: =((B13)*3*150^2)/(R13*$AI$3^2+3*150^2) -> 126.00608 | AJ13: =ROUND((-0.07/(2*S13))*1000000,0) -> 102
A14: 1404 | B14: 577.4 | C14: 509.5 | D14: 459 | E14: 385.3 | F14: 328 | G14: 221.7 | H14: 147.8 | I14: =B14/1000 -> 0.5774 | J14: =LOG10((((3*150*150)*B14)/C14)-((3*150*150))) -> 3.9540294 | K14: =LOG10((((3*150*150)*B14)/D14)-((3*150*150))) -> 4.2408428 | L14: =LOG10((((3*150*150)*B14)/E14)-((3*150*150))) -> 4.5270321 | M14: =LOG10((((3*150*150)*B14)/F14)-((3*150*150))) -> 4.7103264 | N14: =LOG10((((3*150*150)*B14)/G14)-((3*150*150))) -> 5.0346219 | O14: =LOG10((((3*150*150)*B14)/H14)-((3*150*150))) -> 5.2926936 | P14: =10^(INTERCEPT(J14:O14,$J$1:$O$1)) -> 1.0753444 | Q14: =LINEST(J14:O14,$J$1:$O$1) -> 1.697369 | R14: =ROUND(10^((SUM(J14:N14)-2*SUM($J$1:$N$1))/5),3) -> 0.169 | S14: =ROUND(-1.5*((150^2)/(R14*I14))/1000,0) -> -346 | T14: =-4*S14 -> 1384 | U14: =ROUND(150/(R14^0.5),0) -> 365 | V14: =ROUND(150*I14*ATAN((1800*SQRT(3*R14))/(3*150))*SQRT(3/(R14)),0) -> 450 | W14: =ROUND(1/SQRT(R14),3) -> 2.433 | Y14: =ROUND(B14-D14,3) -> 118.4 | Z14: =ROUND(D14-F14,3) -> 131 | AA14: =ROUND(F14-G14,3) -> 106.3 | AC14: =((B14)*3*150^2)/(R14*$AC$3^2+3*150^2) -> 577.4 | AD14: =((B14)*3*150^2)/(R14*$AD$3^2+3*150^2) -> 524.83841 | AE14: =((B14)*3*150^2)/(R14*$AE$3^2+3*150^2) -> 471.21872 | AF14: =((B14)*3*150^2)/(R14*$AF$3^2+3*150^2) -> 383.14532 | AG14: =((B14)*3*150^2)/(R14*$AG$3^2+3*150^2) -> 303.68163 | AH14: =((B14)*3*150^2)/(R14*$AH$3^2+3*150^2) -> 190.68692 | AI14: =((B14)*3*150^2)/(R14*$AI$3^2+3*150^2) -> 125.37638 | AJ14: =ROUND((-0.07/(2*S14))*1000000,0) -> 101
A15: 1396 | B15: 578.3 | C15: 510.5 | D15: 460.9 | E15: 386.9 | F15: 328.4 | G15: 223.2 | H15: 149 | I15: =B15/1000 -> 0.5783 | J15: =LOG10((((3*150*150)*B15)/C15)-((3*150*150))) -> 3.9525377 | K15: =LOG10((((3*150*150)*B15)/D15)-((3*150*150))) -> 4.2353652 | L15: =LOG10((((3*150*150)*B15)/E15)-((3*150*150))) -> 4.523647 | M15: =LOG10((((3*150*150)*B15)/F15)-((3*150*150))) -> 4.7106669 | N15: =LOG10((((3*150*150)*B15)/G15)-((3*150*150))) -> 5.0309603 | O15: =LOG10((((3*150*150)*B15)/H15)-((3*150*150))) -> 5.2888784 | P15: =10^(INTERCEPT(J15:O15,$J$1:$O$1)) -> 1.0720952 | Q15: =LINEST(J15:O15,$J$1:$O$1) -> 1.6967776 | R15: =ROUND(10^((SUM(J15:N15)-2*SUM($J$1:$N$1))/5),3) -> 0.168 | S15: =ROUND(-1.5*((150^2)/(R15*I15))/1000,0) -> -347 | T15: =-4*S15 -> 1388 | U15: =ROUND(150/(R15^0.5),0) -> 366 | V15: =ROUND(150*I15*ATAN((1800*SQRT(3*R15))/(3*150))*SQRT(3/(R15)),0) -> 452 | W15: =ROUND(1/SQRT(R15),3) -> 2.44 | Y15: =ROUND(B15-D15,3) -> 117.4 | Z15: =ROUND(D15-F15,3) -> 132.5 | AA15: =ROUND(F15-G15,3) -> 105.2 | AC15: =((B15)*3*150^2)/(R15*$AC$3^2+3*150^2) -> 578.3 | AD15: =((B15)*3*150^2)/(R15*$AD$3^2+3*150^2) -> 525.93977 | AE15: =((B15)*3*150^2)/(R15*$AE$3^2+3*150^2) -> 472.46732 | AF15: =((B15)*3*150^2)/(R15*$AF$3^2+3*150^2) -> 384.50798 | AG15: =((B15)*3*150^2)/(R15*$AG$3^2+3*150^2) -> 305.01055 | AH15: =((B15)*3*150^2)/(R15*$AH$3^2+3*150^2) -> 191.74403 | AI15: =((B15)*3*150^2)/(R15*$AI$3^2+3*150^2) -> 126.1562 | AJ15: =ROUND((-0.07/(2*S15))*1000000,0) -> 101
A16: =AVERAGE(A4:A7) -> 381 | B16: =AVERAGE(B4:B7) -> 203.125 | C16: =AVERAGE(C4:C7) -> 176.55 | D16: =AVERAGE(D4:D7) -> 158.3 | E16: =AVERAGE(E4:E7) -> 128.6 | F16: =AVERAGE(F4:F7) -> 109.4 | G16: =AVERAGE(G4:G7) -> 68.725 | H16: =AVERAGE(H4:H7) -> 42.1 | ... W16: =AVERAGE(W4:W7) -> 2.272 | Y16: =AVERAGE(Y4:Y7) -> 44.825 | Z16: =AVERAGE(Z4:Z7) -> 48.9 | AA16: =AVERAGE(AA4:AA7) -> 40.675 | AC16: =AVERAGE(AC4:AC7) -> 203.125 | AD16: =AVERAGE(AD4:AD7) -> 182.21154 | AE16: =AVERAGE(AE4:AE7) -> 161.43561 | AF16: =AVERAGE(AF4:AF7) -> 128.47636 | AG16: =AVERAGE(AG4:AG7) -> 99.917771 | AH16: =AVERAGE(AH4:AH7) -> 61.108425 | AI16: =AVERAGE(AI4:AI7) -> 39.583868
A17: =AVERAGE(A8:A11) -> 715.25 | B17: =AVERAGE(B8:B11) -> 351.575 | C17: =AVERAGE(C8:C11) -> 309.25 | D17: =AVERAGE(D8:D11) -> 277.8 | E17: =AVERAGE(E8:E11) -> 232.125 | F17: =AVERAGE(F8:F11) -> 195.1 | G17: =AVERAGE(G8:G11) -> 130.225 | H17: =AVERAGE(H8:H11) -> 85.2 | ... W17: =AVERAGE(W8:W11) -> 2.3855 | Y17: =AVERAGE(Y8:Y11) -> 73.775 | Z17: =AVERAGE(Z8:Z11) -> 82.7 | AA17: =AVERAGE(AA8:AA11) -> 64.875 | AB17: =AC17/AC16 -> 1.7308308 | AC17: =AVERAGE(AC8:AC11) -> 351.575 | AD17: =AVERAGE(AD8:AD11) -> 318.41238 | AE17: =AVERAGE(AE8:AE11) -> 284.82899 | AF17: =AVERAGE(AF8:AF11) -> 230.20013 | AG17: =AVERAGE(AG8:AG11) -> 181.47241 | AH17: =AVERAGE(AH8:AH11) -> 113.08197 | AI17: =AVERAGE(AI8:AI11) -> 74.025447 | AJ17: =AI17/AI16 -> 1.8700913
A18: =AVERAGE(A12:A15) -> 1394.75 | B18: =AVERAGE(B12:B15) -> 580 | C18: =AVERAGE(C12:C15) -> 512.1 | D18: =AVERAGE(D12:D15) -> 460.9 | E18: =AVERAGE(E12:E15) -> 387.45 | F18: =AVERAGE(F12:F15) -> 329.125 | G18: =AVERAGE(G12:G15) -> 222.775 | H18: =AVERAGE(H12:H15) -> 148.725 | ... W18: =AVERAGE(W12:W15) -> 2.43475 | Y18: =AVERAGE(Y12:Y15) -> 119.1 | Z18: =AVERAGE(Z12:Z15) -> 131.775 | AA18: =AVERAGE(AA12:AA15) -> 106.35 | AB18: =AC18/AC16 -> 2.8553846 | AC18: =AVERAGE(AC12:AC15) -> 580 | AD18: =AVERAGE(AD12:AD15) -> 527.27255 | AE18: =AVERAGE(AE12:AE15) -> 473.46912 | AF18: =AVERAGE(AF12:AF15) -> 385.06196 | AG18: =AVERAGE(AG12:AG15) -> 305.26298 | AH18: =AVERAGE(AH12:AH15) -> 191.73555 | AI18: =AVERAGE(AI12:AI15) -> 126.08704 | AJ18: =AI18/AI16 -> 3.1853137
A20: 378 | B20: 393.5 | C20: 359.4 | D20: 312.2 | E20: 241.5 | F20: 182.5 | G20: 96.9 | H20: 53.9 | I20: =B20/1000 -> 0.3935 | J20: =LOG10((((3*150*150)*B20)/C20)-((3*150*150))) -> 3.8064801 | K20: =LOG10((((3*150*150)*B20)/D20)-((3*150*150))) -> 4.2449614 | L20: =LOG10((((3*150*150)*B20)/E20)-((3*150*150))) -> 4.6282302 | M20: =LOG10((((3*150*150)*B20)/F20)-((3*150*150))) -> 4.8923234 | N20: =LOG10((((3*150*150)*B20)/G20)-((3*150*150))) -> 5.3151511 | O20: =LOG10((((3*150*150)*B20)/H20)-((3*150*150))) -> 5.6286827 | P20: =10^(INTERCEPT(J20:O20,$J$1:$O$1)) -> 0.031455147 | Q20: =LINEST(J20:O20,$J$1:$O$1) -> 2.3105227 | R20: =ROUND(10^((SUM(J20:N20)-2*SUM($J$1:$N$1))/5),3) -> 0.205 | S20: =ROUND(-1.5*((150^2)/(R20*I20))/1000,0) -> -418 | T20: =-4*S20 -> 1672 | U20: =ROUND(150/(R20^0.5),0) -> 331 | V20: =ROUND(150*I20*ATAN((1800*SQRT(3*R20))/(3*150))*SQRT(3/(R20)),0) -> 285 | W20: =ROUND(1/SQRT(R20),3) -> 2.209 | Y20: =ROUND(B20-D20,3) -> 81.3 | Z20: =ROUND(D20-F20,3) -> 129.7 | AA20: =ROUND(F20-G20,3) -> 85.6 | AC20: =((B20)*3*150^2)/(R20*$AC$3^2+3*150^2) -> 393.5 | AD20: =((B20)*3*150^2)/(R20*$AD$3^2+3*150^2) -> 350.87517 | AE20: =((B20)*3*150^2)/(R20*$AE$3^2+3*150^2) -> 309.03141 | AF20: =((B20)*3*150^2)/(R20*$AF$3^2+3*150^2) -> 243.65325 | AG20: =((B20)*3*150^2)/(R20*$AG$3^2+3*150^2) -> 187.97771 | AH20: =((B20)*3*150^2)/(R20*$AH$3^2+3*150^2) -> 113.72832 | AI20: =((B20)*3*150^2)/(R20*$AI$3^2+3*150^2) -> 73.23201
A21: 380 | B21: 370.2 | C21: 335.5 | D21: 290.3 | E21: 224.5 | F21: 171 | G21: 93.8 | H21: 55 | I21: =B21/1000 -> 0.3702 | J21: =LOG10((((3*150*150)*B21)/C21)-((3*150*150))) -> 3.8439407 | K21: =LOG10((((3*150*150)*B21)/D21)-((3*150*150))) -> 4.2690035 | L21: =LOG10((((3*150*150)*B21)/E21)-((3*150*150))) -> 4.641547 | M21: =LOG10((((3*150*150)*B21)/F21)-((3*150*150))) -> 4.895597 | N21: =LOG10((((3*150*150)*B21)/G21)-((3*150*150))) -> 5.298639 | O21: =LOG10((((3*150*150)*B21)/H21)-((3*150*150))) -> 5.5875273 | P21: =10^(INTERCEPT(J21:O21,$J$1:$O$1)) -> 0.057502287 | Q21: =LINEST(J21:O21,$J$1:$O$1) -> 2.2150021 | R21: =ROUND(10^((SUM(J21:N21)-2*SUM($J$1:$N$1))/5),3) -> 0.211 | S21: =ROUND(-1.5*((150^2)/(R21*I21))/1000,0) -> -432 | T21: =-4*S21 -> 1728 | U21: =ROUND(150/(R21^0.5),0) -> 327 | V21: =ROUND(150*I21*ATAN((1800*SQRT(3*R21))/(3*150))*SQRT(3/(R21)),0) -> 265 | W21: =ROUND(1/SQRT(R21),3) -> 2.177 | Y21: =ROUND(B21-D21,3) -> 79.9 | Z21: =ROUND(D21-F21,3) -> 119.3 | AA21: =ROUND(F21-G21,3) -> 77.2 | AC21: =((B21)*3*150^2)/(R21*$AC$3^2+3*150^2) -> 370.2 | AD21: =((B21)*3*150^2)/(R21*$AD$3^2+3*150^2) -> 329.05583 | AE21: =((B21)*3*150^2)/(R21*$AE$3^2+3*150^2) -> 288.91779 | AF21: =((B21)*3*150^2)/(R21*$AF$3^2+3*150^2) -> 226.69933 | AG21: =((B21)*3*150^2)/(R21*$AG$3^2+3*150^2) -> 174.18444 | AH21: =((B21)*3*150^2)/(R21*$AH$3^2+3*150^2) -> 104.81314 | AI21: =((B21)*3*150^2)/(R21*$AI$3^2+3*150^2) -> 67.292778
A22: 383 | B22: 365 | C22: 332.2 | D22: 287 | E22: 223 | F22: 170.3 | G22: 94.7 | H22: 55.8 | I22: =B22/1000 -> 0.365 | J22: =LOG10((((3*150*150)*B22)/C22)-((3*150*150))) -> 3.823778 | K22: =LOG10((((3*150*150)*B22)/D22)-((3*150*150))) -> 4.2635165 | L22: =LOG10((((3*150*150)*B22)/E22)-((3*150*150))) -> 4.6332873 | M22: =LOG10((((3*150*150)*B22)/F22)-((3*150*150))) -> 4.8874551 | N22: =LOG10((((3*150*150)*B22)/G22)-((3*150*150))) -> 5.2847998 | O22: =LOG10((((3*150*150)*B22)/H22)-((3*150*150))) -> 5.5729091 | P22: =10^(INTERCEPT(J22:O22,$J$1:$O$1)) -> 0.055590654 | Q22: =LINEST(J22:O22,$J$1:$O$1) -> 2.2160851 | R22: =ROUND(10^((SUM(J22:N22)-2*SUM($J$1:$N$1))/5),3) -> 0.206 | S22: =ROUND(-1.5*((150^2)/(R22*I22))/1000,0) -> -449 | T22: =-4*S22 -> 1796 | U22: =ROUND(150/(R22^0.5),0) -> 330 | V22: =ROUND(150*I22*ATAN((1800*SQRT(3*R22))/(3*150))*SQRT(3/(R22)),0) -> 264 | W22: =ROUND(1/SQRT(R22),3) -> 2.203 | Y22: =ROUND(B22-D22,3) -> 78 | Z22: =ROUND(D22-F22,3) -> 116.7 | AA22: =ROUND(F22-G22,3) -> 75.6 | AC22: =((B22)*3*150^2)/(R22*$AC$3^2+3*150^2) -> 365 | AD22: =((B22)*3*150^2)/(R22*$AD$3^2+3*150^2) -> 325.29047 | AE22: =((B22)*3*150^2)/(R22*$AE$3^2+3*150^2) -> 286.34937 | AF22: =((B22)*3*150^2)/(R22*$AF$3^2+3*150^2) -> 225.58714 | AG22: =((B22)*3*150^2)/(R22*$AG$3^2+3*150^2) -> 173.91995 | AH22: =((B22)*3*150^2)/(R22*$AH$3^2+3*150^2) -> 105.12673 | AI22: =((B22)*3*150^2)/(R22*$AI$3^2+3*150^2) -> 67.659417
A23: 383 | B23: 363 | C23: 329.9 | D23: 285 | E23: 221.7 | F23: 169.7 | G23: 94.8 | H23: 56 | I23: =B23/1000 -> 0.363 | J23: =LOG10((((3*150*150)*B23)/C23)-((3*150*150))) -> 3.8307495 | K23: =LOG10((((3*150*150)*B23)/D23)-((3*150*150))) -> 4.2665535 | L23: =LOG10((((3*150*150)*B23)/E23)-((3*150*150))) -> 4.6336802 | M23: =LOG10((((3*150*150)*B23)/F23)-((3*150*150))) -> 4.8858538 | N23: =LOG10((((3*150*150)*B23)/G23)-((3*150*150))) -> 5.2809542 | O23: =LOG10((((3*150*150)*B23)/H23)-((3*150*150))) -> 5.5682541 | P23: =10^(INTERCEPT(J23:O23,$J$1:$O$1)) -> 0.061017518 | Q23: =LINEST(J23:O23,$J$1:$O$1) -> 2.2011607 | R23: =ROUND(10^((SUM(J23:N23)-2*SUM($J$1:$N$1))/5),3) -> 0.206 | S23: =ROUND(-1.5*((150^2)/(R23*I23))/1000,0) -> -451 | T23: =-4*S23 -> 1804 | U23: =ROUND(150/(R23^0.5),0) -> 330 | V23: =ROUND(150*I23*ATAN((1800*SQRT(3*R23))/(3*150))*SQRT(3/(R23)),0) -> 262 | W23: =ROUND(1/SQRT(R23),3) -> 2.203 | Y23: =ROUND(B23-D23,3) -> 78 | Z23: =ROUND(D23-F23,3) -> 115.3 | AA23: =ROUND(F23-G23,3) -> 74.9 | AC23: =((B23)*3*150^2)/(R23*$AC$3^2+3*150^2) -> 363 | AD23: =((B23)*3*150^2)/(R23*$AD$3^2+3*150^2) -> 323.50805 | AE23: =((B23)*3*150^2)/(R23*$AE$3^2+3*150^2) -> 284.78033 | AF23: =((B23)*3*150^2)/(R23*$AF$3^2+3*150^2) -> 224.35105 | AG23: =((B23)*3*150^2)/(R23*$AG$3^2+3*150^2) -> 172.96696 | AH23: =((B23)*3*150^2)/(R23*$AH$3^2+3*150^2) -> 104.55069 | AI23: =((B23)*3*150^2)/(R23*$AI$3^2+3*150^2) -> 67.28868
A24: 724 | B24: 640.8 | C24: 587.1 | D24: 510.9 | E24: 402.6 | F24: 311.5 | G24: 178.2 | H24: 105 | I24: =B24/1000 -> 0.6408 | J24: =LOG10((((3*150*150)*B24)/C24)-((3*150*150))) -> 3.790566 | K24: =LOG10((((3*150*150)*B24)/D24)-((3*150*150))) -> 4.234577 | L24: =LOG10((((3*150*150)*B24)/E24)-((3*150*150))) -> 4.6013718 | M24: =LOG10((((3*150*150)*B24)/F24)-((3*150*150))) -> 4.8534375 | N24: =LOG10((((3*150*150)*B24)/G24)-((3*150*150))) -> 5.2436017 | O24: =LOG10((((3*150*150)*B24)/H24)-((3*150*150))) -> 5.5371172 | P24: =10^(INTERCEPT(J24:O24,$J$1:$O$1)) -> 0.054520528 | Q24: =LINEST(J24:O24,$J$1:$O$1) -> 2.206578 | R24: =ROUND(10^((SUM(J24:N24)-2*SUM($J$1:$N$1))/5),3) -> 0.19 | S24: =ROUND(-1.5*((150^2)/(R24*I24))/1000,0) -> -277 | T24: =-4*S24 -> 1108 | U24: =ROUND(150/(R24^0.5),0) -> 344 | V24: =ROUND(150*I24*ATAN((1800*SQRT(3*R24))/(3*150))*SQRT(3/(R24)),0) -> 478 | W24: =ROUND(1/SQRT(R24),3) -> 2.294 | Y24: =ROUND(B24-D24,3) -> 129.9 | Z24: =ROUND(D24-F24,3) -> 199.4 | AA24: =ROUND(F24-G24,3) -> 133.3 | AC24: =((B24)*3*150^2)/(R24*$AC$3^2+3*150^2) -> 640.8 | AD24: =((B24)*3*150^2)/(R24*$AD$3^2+3*150^2) -> 575.95206 | AE24: =((B24)*3*150^2)/(R24*$AE$3^2+3*150^2) -> 511.2766 | AF24: =((B24)*3*150^2)/(R24*$AF$3^2+3*150^2) -> 408.15287 | AG24: =((B24)*3*150^2)/(R24*$AG$3^2+3*150^2) -> 318.27815 | AH24: =((B24)*3*150^2)/(R24*$AH$3^2+3*150^2) -> 195.36585 | AI24: =((B24)*3*150^2)/(R24*$AI$3^2+3*150^2) -> 126.80739
A25: 715 | B25: 618.5 | C25: 565 | D25: 493.5 | E25: 389.9 | F25: 302.5 | G25: 175 | H25: 104.2 | I25: =B25/1000 -> 0.6185 | J25: =LOG10((((3*150*150)*B25)/C25)-((3*150*150))) -> 3.8056091 | K25: =LOG10((((3*150*150)*B25)/D25)-((3*150*150))) -> 4.2329266 | L25: =LOG10((((3*150*150)*B25)/E25)-((3*150*150))) -> 4.5974268 | M25: =LOG10((((3*150*150)*B25)/F25)-((3*150*150))) -> 4.8482655 | N25: =LOG10((((3*150*150)*B25)/G25)-((3*150*150))) -> 5.2331593 | O25: =LOG10((((3*150*150)*B25)/H25)-((3*150*150))) -> 5.5226526 | P25: =10^(INTERCEPT(J25:O25,$J$1:$O$1)) -> 0.066261386 | Q25: =LINEST(J25:O25,$J$1:$O$1) -> 2.1740202 | R25: =ROUND(10^((SUM(J25:N25)-2*SUM($J$1:$N$1))/5),3) -> 0.19 | S25: =ROUND(-1.5*((150^2)/(R25*I25))/1000,0) -> -287 | T25: =-4*S25 -> 1148 | U25: =ROUND(150/(R25^0.5),0) -> 344 | V25: =ROUND(150*I25*ATAN((1800*SQRT(3*R25))/(3*150))*SQRT(3/(R25)),0) -> 461 | W25: =ROUND(1/SQRT(R25),3) -> 2.294 | Y25: =ROUND(B25-D25,3) -> 125 | Z25: =ROUND(D25-F25,3) -> 191 | AA25: =ROUND(F25-G25,3) -> 127.5 | AC25: =((B25)*3*150^2)/(R25*$AC$3^2+3*150^2) -> 618.5 | AD25: =((B25)*3*150^2)/(R25*$AD$3^2+3*150^2) -> 555.90879 | AE25: =((B25)*3*150^2)/(R25*$AE$3^2+3*150^2) -> 493.48404 | AF25: =((B25)*3*150^2)/(R25*$AF$3^2+3*150^2) -> 393.94904 | AG25: =((B25)*3*150^2)/(R25*$AG$3^2+3*150^2) -> 307.20199 | AH25: =((B25)*3*150^2)/(R25*$AH$3^2+3*150^2) -> 188.56707 | AI25: =((B25)*3*150^2)/(R25*$AI$3^2+3*150^2) -> 122.39446
A26: 712 | B26: 611.2 | C26: 555.6 | D26: 486.1 | E26: 385.4 | F26: 299 | G26: 173.8 | H26: 103.9 | I26: =B26/1000 -> 0.6112 | J26: =LOG10((((3*150*150)*B26)/C26)-((3*150*150))) -> 3.8296163 | K26: =LOG10((((3*150*150)*B26)/D26)-((3*150*150))) -> 4.2398355 | L26: =LOG10((((3*150*150)*B26)/E26)-((3*150*150))) -> 4.597116 | M26: =LOG10((((3*150*150)*B26)/F26)-((3*150*150))) -> 4.8480655 | N26: =LOG10((((3*150*150)*B26)/G26)-((3*150*150))) -> 5.2301328 | O26: =LOG10((((3*150*150)*B26)/H26)-((3*150*150))) -> 5.5179531 | P26: =10^(INTERCEPT(J26:O26,$J$1:$O$1)) -> 0.081865096 | Q26: =LINEST(J26:O26,$J$1:$O$1) -> 2.1414922 | R26: =ROUND(10^((SUM(J26:N26)-2*SUM($J$1:$N$1))/5),3) -> 0.192 | S26: =ROUND(-1.5*((150^2)/(R26*I26))/1000,0) -> -288 | T26: =-4*S26 -> 1152 | U26: =ROUND(150/(R26^0.5),0) -> 342 | V26: =ROUND(150*I26*ATAN((1800*SQRT(3*R26))/(3*150))*SQRT(3/(R26)),0) -> 454 | W26: =ROUND(1/SQRT(R26),3) -> 2.282 | Y26: =ROUND(B26-D26,3) -> 125.1 | Z26: =ROUND(D26-F26,3) -> 187.1 | AA26: =ROUND(F26-G26,3) -> 125.2 | AC26: =((B26)*3*150^2)/(R26*$AC$3^2+3*150^2) -> 611.2 | AD26: =((B26)*3*150^2)/(R26*$AD$3^2+3*150^2) -> 548.76297 | AE26: =((B26)*3*150^2)/(R26*$AE$3^2+3*150^2) -> 486.6242 | AF26: =((B26)*3*150^2)/(R26*$AF$3^2+3*150^2) -> 387.81726 | AG26: =((B26)*3*150^2)/(R26*$AG$3^2+3*150^2) -> 301.97628 | AH26: =((B26)*3*150^2)/(R26*$AH$3^2+3*150^2) -> 184.98789 | AI26: =((B26)*3*150^2)/(R26*$AI$3^2+3*150^2) -> 119.93721
A27: 710 | B27: 607.2 | C27: 550.4 | D27: 481.8 | E27: 383.1 | F27: 297.1 | G27: 172.9 | H27: 103.5 | I27: =B27/1000 -> 0.6072 | J27: =LOG10((((3*150*150)*B27)/C27)-((3*150*150))) -> 3.8429737 | K27: =LOG10((((3*150*150)*B27)/D27)-((3*150*150))) -> 4.2447345 | L27: =LOG10((((3*150*150)*B27)/E27)-((3*150*150))) -> 4.5964335 | M27: =LOG10((((3*150*150)*B27)/F27)-((3*150*150))) -> 4.8479029 | N27: =LOG10((((3*150*150)*B27)/G27)-((3*150*150))) -> 5.2292986 | O27: =LOG10((((3*150*150)*B27)/H27)-((3*150*150))) -> 5.5165354 | P27: =10^(INTERCEPT(J27:O27,$J$1:$O$1)) -> 0.091588664 | Q27: =LINEST(J27:O27,$J$1:$O$1) -> 2.1244203 | R27: =ROUND(10^((SUM(J27:N27)-2*SUM($J$1:$N$1))/5),3) -> 0.194 | S27: =ROUND(-1.5*((150^2)/(R27*I27))/1000,0) -> -287 | T27: =-4*S27 -> 1148 | U27: =ROUND(150/(R27^0.5),0) -> 341 | V27: =ROUND(150*I27*ATAN((1800*SQRT(3*R27))/(3*150))*SQRT(3/(R27)),0) -> 449 | W27: =ROUND(1/SQRT(R27),3) -> 2.27 | Y27: =ROUND(B27-D27,3) -> 125.4 | Z27: =ROUND(D27-F27,3) -> 184.7 | AA27: =ROUND(F27-G27,3) -> 124.2 | AC27: =((B27)*3*150^2)/(R27*$AC$3^2+3*150^2) -> 607.2 | AD27: =((B27)*3*150^2)/(R27*$AD$3^2+3*150^2) -> 544.59208 | AE27: =((B27)*3*150^2)/(R27*$AE$3^2+3*150^2) -> 482.41525 | AF27: =((B27)*3*150^2)/(R27*$AF$3^2+3*150^2) -> 383.81795 | AG27: =((B27)*3*150^2)/(R27*$AG$3^2+3*150^2) -> 298.42726 | AH27: =((B27)*3*150^2)/(R27*$AH$3^2+3*150^2) -> 182.45192 | AI27: =((B27)*3*150^2)/(R27*$AI$3^2+3*150^2) -> 118.16295
A28: 1372 | B28: 1012 | C28: 951.3 | D28: 816.3 | E28: 660 | F28: 517.6 | G28: 309.1 | H28: 188.9 | I28: =B28/1000 -> 1.012 | J28: =LOG10((((3*150*150)*B28)/C28)-((3*150*150))) -> 3.634175 | K28: =LOG10((((3*150*150)*B28)/D28)-((3*150*150))) -> 4.2090448 | L28: =LOG10((((3*150*150)*B28)/E28)-((3*150*150))) -> 4.5563025 | M28: =LOG10((((3*150*150)*B28)/F28)-((3*150*150))) -> 4.809388 | N28: =LOG10((((3*150*150)*B28)/G28)-((3*150*150))) -> 5.1860983 | O28: =LOG10((((3*150*150)*B28)/H28)-((3*150*150))) -> 5.4685244 | P28: =10^(INTERCEPT(J28:O28,$J$1:$O$1)) -> 0.030618249 | Q28: =LINEST(J28:O28,$J$1:$O$1) -> 2.27469 | R28: =ROUND(10^((SUM(J28:N28)-2*SUM($J$1:$N$1))/5),3) -> 0.163 | S28: =ROUND(-1.5*((150^2)/(R28*I28))/1000,0) -> -205 | T28: =-4*S28 -> 820 | U28: =ROUND(150/(R28^0.5),0) -> 372 | V28: =ROUND(150*I28*ATAN((1800*SQRT(3*R28))/(3*150))*SQRT(3/(R28)),0) -> 799 | W28: =ROUND(1/SQRT(R28),3) -> 2.477 | Y28: =ROUND(B28-D28,3) -> 195.7 | Z28: =ROUND(D28-F28,3) -> 298.7 | AA28: =ROUND(F28-G28,3) -> 208.5 | AC28: =((B28)*3*150^2)/(R28*$AC$3^2+3*150^2) -> 1012 | AD28: =((B28)*3*150^2)/(R28*$AD$3^2+3*150^2) -> 922.85869 | AE28: =((B28)*3*150^2)/(R28*$AE$3^2+3*150^2) -> 831.3253 | AF28: =((B28)*3*150^2)/(R28*$AF$3^2+3*150^2) -> 679.65077 | AG28: =((B28)*3*150^2)/(R28*$AG$3^2+3*150^2) -> 541.36947 | AH28: =((B28)*3*150^2)/(R28*$AH$3^2+3*150^2) -> 342.35453 | AI28: =((B28)*3*150^2)/(R28*$AI$3^2+3*150^2) -> 226.0274
A29: 1407 | B29: 1025.4 | C29: 955.7 | D29: 826.2 | E29: 674.8 | F29: 528.5 | G29: 319.1 | H29: 197.5 | I29: =B29/1000 -> 1.0254 | J29: =LOG10((((3*150*150)*B29)/C29)-((3*150*150))) -> 3.692215 | K29: =LOG10((((3*150*150)*B29)/D29)-((3*150*150))) -> 4.2115079 | L29: =LOG10((((3*150*150)*B29)/E29)-((3*150*150))) -> 4.5449406 | M29: =LOG10((((3*150*150)*B29)/F29)-((3*150*150))) -> 4.8025278 | N29: =LOG10((((3*150*150)*B29)/G29)-((3*150*150))) -> 5.1743662 | O29: =LOG10((((3*150*150)*B29)/H29)-((3*150*150))) -> 5.4517146 | P29: =10^(INTERCEPT(J29:O29,$J$1:$O$1)) -> 0.050048869 | Q29: =LINEST(J29:O29,$J$1:$O$1) -> 2.1967026 | R29: =ROUND(10^((SUM(J29:N29)-2*SUM($J$1:$N$1))/5),3) -> 0.166 | S29: =ROUND(-1.5*((150^2)/(R29*I29))/1000,0) -> -198 | T29: =-4*S29 -> 792 | U29: =ROUND(150/(R29^0.5),0) -> 368 | V29: =ROUND(150*I29*ATAN((1800*SQRT(3*R29))/(3*150))*SQRT(3/(R29)),0) -> 804 | W29: =ROUND(1/SQRT(R29),3) -> 2.454 | Y29: =ROUND(B29-D29,3) -> 199.2 | Z29: =ROUND(D29-F29,3) -> 297.7 | AA29: =ROUND(F29-G29,3) -> 209.4 | AC29: =((B29)*3*150^2)/(R29*$AC$3^2+3*150^2) -> 1025.4 | AD29: =((B29)*3*150^2)/(R29*$AD$3^2+3*150^2) -> 933.56488 | AE29: =((B29)*3*150^2)/(R29*$AE$3^2+3*150^2) -> 839.57424 | AF29: =((B29)*3*150^2)/(R29*$AF$3^2+3*150^2) -> 684.51268 | AG29: =((B29)*3*150^2)/(R29*$AG$3^2+3*150^2) -> 543.8826 | AH29: =((B29)*3*150^2)/(R29*$AH$3^2+3*150^2) -> 342.7139 | AI29: =((B29)*3*150^2)/(R29*$AI$3^2+3*150^2) -> 225.79272
A30: 1404 | B30: 1020.2 | C30: 950 | D30: 826.7 | E30: 674.8 | F30: 528.9 | G30: 319.4 | H30: 198.1 | I30: =B30/1000 -> 1.0202 | J30: =LOG10((((3*150*150)*B30)/C30)-((3*150*150))) -> 3.6979173 | K30: =LOG10((((3*150*150)*B30)/D30)-((3*150*150))) -> 4.1986368 | L30: =LOG10((((3*150*150)*B30)/E30)-((3*150*150))) -> 4.538451 | M30: =LOG10((((3*150*150)*B30)/F30)-((3*150*150))) -> 4.797277 | N30: =LOG10((((3*150*150)*B30)/G30)-((3*150*150))) -> 5.170563 | O30: =LOG10((((3*150*150)*B30)/H30)-((3*150*150))) -> 5.4473439 | P30: =10^(INTERCEPT(J30:O30,$J$1:$O$1)) -> 0.050962682 | Q30: =LINEST(J30:O30,$J$1:$O$1) -> 2.1921326 | R30: =ROUND(10^((SUM(J30:N30)-2*SUM($J$1:$N$1))/5),3) -> 0.164 | S30: =ROUND(-1.5*((150^2)/(R30*I30))/1000,0) -> -202 | T30: =-4*S30 -> 808 | U30: =ROUND(150/(R30^0.5),0) -> 370 | V30: =ROUND(150*I30*ATAN((1800*SQRT(3*R30))/(3*150))*SQRT(3/(R30)),0) -> 804 | W30: =ROUND(1/SQRT(R30),3) -> 2.469 | Y30: =ROUND(B30-D30,3) -> 193.5 | Z30: =ROUND(D30-F30,3) -> 297.8 | AA30: =ROUND(F30-G30,3) -> 209.5 | AC30: =((B30)*3*150^2)/(R30*$AC$3^2+3*150^2) -> 1020.2 | AD30: =((B30)*3*150^2)/(R30*$AD$3^2+3*150^2) -> 929.83392 | AE30: =((B30)*3*150^2)/(R30*$AE$3^2+3*150^2) -> 837.14442 | AF30: =((B30)*3*150^2)/(R30*$AF$3^2+3*150^2) -> 683.78016 | AG30: =((B30)*3*150^2)/(R30*$AG$3^2+3*150^2) -> 544.20341 | AH30: =((B30)*3*150^2)/(R30*$AH$3^2+3*150^2) -> 343.73315 | AI30: =((B30)*3*150^2)/(R30*$AI$3^2+3*150^2) -> 226.7783
A31: 1396 | B31: 1016.7 | C31: 944.5 | D31: 822.7 | E31: 672.9 | F31: 528.3 | G31: 318.8 | H31: 198.2 | I31: =B31/1000 -> 1.0167 | J31: =LOG10((((3*150*150)*B31)/C31)-((3*150*150))) -> 3.712639 | K31: =LOG10((((3*150*150)*B31)/D31)-((3*150*150))) -> 4.201864 | L31: =LOG10((((3*150*150)*B31)/E31)-((3*150*150))) -> 4.5376591 | M31: =LOG10((((3*150*150)*B31)/F31)-((3*150*150))) -> 4.7951988 | N31: =LOG10((((3*150*150)*B31)/G31)-((3*150*150))) -> 5.1695787 | O31: =LOG10((((3*150*150)*B31)/H31)-((3*150*150))) -> 5.4452188 | P31: =10^(INTERCEPT(J31:O31,$J$1:$O$1)) -> 0.057448991 | Q31: =LINEST(J31:O31,$J$1:$O$1) -> 2.17365 | R31: =ROUND(10^((SUM(J31:N31)-2*SUM($J$1:$N$1))/5),3) -> 0.165 | S31: =ROUND(-1.5*((150^2)/(R31*I31))/1000,0) -> -201 | T31: =-4*S31 -> 804 | U31: =ROUND(150/(R31^0.5),0) -> 369 | V31: =ROUND(150*I31*ATAN((1800*SQRT(3*R31))/(3*150))*SQRT(3/(R31)),0) -> 799 | W31: =ROUND(1/SQRT(R31),3) -> 2.462 | Y31: =ROUND(B31-D31,3) -> 194 | Z31: =ROUND(D31-F31,3) -> 294.4 | AA31: =ROUND(F31-G31,3) -> 209.5 | AC31: =((B31)*3*150^2)/(R31*$AC$3^2+3*150^2) -> 1016.7 | AD31: =((B31)*3*150^2)/(R31*$AD$3^2+3*150^2) -> 926.14372 | AE31: =((B31)*3*150^2)/(R31*$AE$3^2+3*150^2) -> 833.36066 | AF31: =((B31)*3*150^2)/(R31*$AF$3^2+3*150^2) -> 680.06689 | AG31: =((B31)*3*150^2)/(R31*$AG$3^2+3*150^2) -> 540.79787 | AH31: =((B31)*3*150^2)/(R31*$AH$3^2+3*150^2) -> 341.1745 | AI31: =((B31)*3*150^2)/(R31*$AI$3^2+3*150^2) -> 224.93363
A32: =AVERAGE(A20:A23) -> 381 | B32: =AVERAGE(B20:B23) -> 372.925 | C32: =AVERAGE(C20:C23) -> 339.25 | D32: =AVERAGE(D20:D23) -> 293.625 | E32: =AVERAGE(E20:E23) -> 227.675 | F32: =AVERAGE(F20:F23) -> 173.375 | G32: =AVERAGE(G20:G23) -> 95.05 | H32: =AVERAGE(H20:H23) -> 55.175 | ... W32: =AVERAGE(W20:W23) -> 2.198 | X32: =SLOPE(W32:W34,A32:A34) -> 0.00026413033 | Y32: =AVERAGE(Y20:Y23) -> 79.3 | Z32: =AVERAGE(Z20:Z23) -> 120.25 | AA32: =AVERAGE(AA20:AA23) -> 78.325 | AC32: =AVERAGE(AC20:AC23) -> 372.925 | AD32: =AVERAGE(AD20:AD23) -> 332.18238 | AE32: =AVERAGE(AE20:AE23) -> 292.26973 | AF32: =AVERAGE(AF20:AF23) -> 230.07269 | AG32: =AVERAGE(AG20:AG23) -> 177.26227 | AH32: =AVERAGE(AH20:AH23) -> 107.05472 | AI32: =AVERAGE(AI20:AI23) -> 68.868221
A33: =AVERAGE(A24:A27) -> 715.25 | B33: =AVERAGE(B24:B27) -> 619.425 | C33: =AVERAGE(C24:C27) -> 564.525 | D33: =AVERAGE(D24:D27) -> 493.075 | E33: =AVERAGE(E24:E27) -> 390.25 | F33: =AVERAGE(F24:F27) -> 302.525 | G33: =AVERAGE(G24:G27) -> 174.975 | H33: =AVERAGE(H24:H27) -> 104.15 | ... W33: =AVERAGE(W24:W27) -> 2.285 | Y33: =AVERAGE(Y24:Y27) -> 126.35 | Z33: =AVERAGE(Z24:Z27) -> 190.55 | AA33: =AVERAGE(AA24:AA27) -> 127.55 | AB33: =AC33/AC32 -> 1.6609908 | AC33: =AVERAGE(AC24:AC27) -> 619.425 | AD33: =AVERAGE(AD24:AD27) -> 556.30398 | AE33: =AVERAGE(AE24:AE27) -> 493.45002 | AF33: =AVERAGE(AF24:AF27) -> 393.43428 | AG33: =AVERAGE(AG24:AG27) -> 306.47092 | AH33: =AVERAGE(AH24:AH27) -> 187.84319 | AI33: =AVERAGE(AI24:AI27) -> 121.8255 | AJ33: =AI33/AI32 -> 1.7689654
A34: =AVERAGE(A28:A31) -> 1394.75 | B34: =AVERAGE(B28:B31) -> 1018.575 | C34: =AVERAGE(C28:C31) -> 950.375 | D34: =AVERAGE(D28:D31) -> 822.975 | E34: =AVERAGE(E28:E31) -> 670.625 | F34: =AVERAGE(F28:F31) -> 525.825 | G34: =AVERAGE(G28:G31) -> 316.6 | H34: =AVERAGE(H28:H31) -> 195.675 | ... W34: =AVERAGE(W28:W31) -> 2.4655 | Y34: =AVERAGE(Y28:Y31) -> 195.6 | Z34: =AVERAGE(Z28:Z31) -> 297.15 | AA34: =AVERAGE(AA28:AA31) -> 209.225 | AB34: =AC34/AC32 -> 2.7313133 | AC34: =AVERAGE(AC28:AC31) -> 1018.575 | AD34: =AVERAGE(AD28:AD31) -> 928.1003 | AE34: =AVERAGE(AE28:AE31) -> 835.35115 | AF34: =AVERAGE(AF28:AF31) -> 682.00263 | AG34: =AVERAGE(AG28:AG31) -> 542.56334 | AH34: =AVERAGE(AH28:AH31) -> 342.49402 | AI34: =AVERAGE(AI28:AI31) -> 225.88301 | AJ34: =AI34/AI32 -> 3.279931
A35: 370 | B35: 371.1 | C35: 348.3 | D35: 306.7 | E35: 238.6 | F35: 181 | G35: 100.3 | H35: 56.5 | I35: =B35/1000 -> 0.3711 | J35: =LOG10((((3*150*150)*B35)/C35)-((3*150*150))) -> 3.6452851 | K35: =LOG10((((3*150*150)*B35)/D35)-((3*150*150))) -> 4.1514759 | L35: =LOG10((((3*150*150)*B35)/E35)-((3*150*150))) -> 4.5738492 | M35: =LOG10((((3*150*150)*B35)/F35)-((3*150*150))) -> 4.8506073 | N35: =LOG10((((3*150*150)*B35)/G35)-((3*150*150))) -> 5.2606515 | O35: =LOG10((((3*150*150)*B35)/H35)-((3*150*150))) -> 5.575014 | P35: =10^(INTERCEPT(J35:O35,$J$1:$O$1)) -> 0.012038156 | Q35: =LINEST(J35:O35,$J$1:$O$1) -> 2.4363524 | R35: =ROUND(10^((SUM(J35:N35)-2*SUM($J$1:$N$1))/5),3) -> 0.17 | S35: =ROUND(-1.5*((150^2)/(R35*I35))/1000,0) -> -535 | T35: =-4*S35 -> 2140 | U35: =ROUND(150/(R35^0.5),0) -> 364 | V35: =ROUND(150*I35*ATAN((1800*SQRT(3*R35))/(3*150))*SQRT(3/(R35)),0) -> 289 | W35: =ROUND(1/SQRT(R35),3) -> 2.425 | Y35: =ROUND(B35-D35,3) -> 64.4 | Z35: =ROUND(D35-F35,3) -> 125.7 | AA35: =ROUND(F35-G35,3) -> 80.7 | AC35: =((B35)*3*150^2)/(R35*$AC$3^2+3*150^2) -> 371.1 | AD35: =((B35)*3*150^2)/(R35*$AD$3^2+3*150^2) -> 337.13661 | AE35: =((B35)*3*150^2)/(R35*$AE$3^2+3*150^2) -> 302.52717 | AF35: =((B35)*3*150^2)/(R35*$AF$3^2+3*150^2) -> 245.76159 | AG35: =((B35)*3*150^2)/(R35*$AG$3^2+3*150^2) -> 194.63287 | AH35: =((B35)*3*150^2)/(R35*$AH$3^2+3*150^2) -> 122.07237 | AI35: =((B35)*3*150^2)/(R35*$AI$3^2+3*150^2) -> 80.208934
A36: 359 | B36: 353.3 | C36: 329.9 | D36: 291 | E36: 226.6 | F36: 174.3 | G36: 98.2 | H36: 56.5 | I36: =B36/1000 -> 0.3533 | J36: =LOG10((((3*150*150)*B36)/C36)-((3*150*150))) -> 3.6801373 | K36: =LOG10((((3*150*150)*B36)/D36)-((3*150*150))) -> 4.1598988 | L36: =LOG10((((3*150*150)*B36)/E36)-((3*150*150))) -> 4.5768205 | M36: =LOG10((((3*150*150)*B36)/F36)-((3*150*150))) -> 4.8408594 | N36: =LOG10((((3*150*150)*B36)/G36)-((3*150*150))) -> 5.2439027 | O36: =LOG10((((3*150*150)*B36)/H36)-((3*150*150))) -> 5.5497192 | P36: =10^(INTERCEPT(J36:O36,$J$1:$O$1)) -> 0.018782399 | Q36: =LINEST(J36:O36,$J$1:$O$1) -> 2.3646479 | R36: =ROUND(10^((SUM(J36:N36)-2*SUM($J$1:$N$1))/5),3) -> 0.172 | S36: =ROUND(-1.5*((150^2)/(R36*I36))/1000,0) -> -555 | T36: =-4*S36 -> 2220 | U36: =ROUND(150/(R36^0.5),0) -> 362 | V36: =ROUND(150*I36*ATAN((1800*SQRT(3*R36))/(3*150))*SQRT(3/(R36)),0) -> 274 | W36: =ROUND(1/SQRT(R36),3) -> 2.411 | Y36: =ROUND(B36-D36,3) -> 62.3 | Z36: =ROUND(D36-F36,3) -> 116.7 | AA36: =ROUND(F36-G36,3) -> 76.1 | AC36: =((B36)*3*150^2)/(R36*$AC$3^2+3*150^2) -> 353.3 | AD36: =((B36)*3*150^2)/(R36*$AD$3^2+3*150^2) -> 320.62046 | AE36: =((B36)*3*150^2)/(R36*$AE$3^2+3*150^2) -> 287.39154 | AF36: =((B36)*3*150^2)/(R36*$AF$3^2+3*150^2) -> 233.04749 | AG36: =((B36)*3*150^2)/(R36*$AG$3^2+3*150^2) -> 184.26634 | AH36: =((B36)*3*150^2)/(R36*$AH$3^2+3*150^2) -> 115.30679 | AI36: =((B36)*3*150^2)/(R36*$AI$3^2+3*150^2) -> 75.663906
A37: 360 | B37: 346.2 | C37: 323 | D37: 285.2 | E37: 222.7 | F37: 171.9 | G37: 97.3 | H37: 56.3 | I37: =B37/1000 -> 0.3462 | J37: =LOG10((((3*150*150)*B37)/C37)-((3*150*150))) -> 3.6855892 | K37: =LOG10((((3*150*150)*B37)/D37)-((3*150*150))) -> 4.1594841 | L37: =LOG10((((3*150*150)*B37)/E37)-((3*150*150))) -> 4.5732505 | M37: =LOG10((((3*150*150)*B37)/F37)-((3*150*150))) -> 4.8353253 | N37: =LOG10((((3*150*150)*B37)/G37)-((3*150*150))) -> 5.2372158 | O37: =LOG10((((3*150*150)*B37)/H37)-((3*150*150))) -> 5.5410436 | P37: =10^(INTERCEPT(J37:O37,$J$1:$O$1)) -> 0.020717632 | Q37: =LINEST(J37:O37,$J$1:$O$1) -> 2.3477197 | R37: =ROUND(10^((SUM(J37:N37)-2*SUM($J$1:$N$1))/5),3) -> 0.171 | S37: =ROUND(-1.5*((150^2)/(R37*I37))/1000,0) -> -570 | T37: =-4*S37 -> 2280 | U37: =ROUND(150/(R37^0.5),0) -> 363 | V37: =ROUND(150*I37*ATAN((1800*SQRT(3*R37))/(3*150))*SQRT(3/(R37)),0) -> 269 | W37: =ROUND(1/SQRT(R37),3) -> 2.418 | Y37: =ROUND(B37-D37,3) -> 61 | Z37: =ROUND(D37-F37,3) -> 113.3 | AA37: =ROUND(F37-G37,3) -> 74.6 | AC37: =((B37)*3*150^2)/(R37*$AC$3^2+3*150^2) -> 346.2 | AD37: =((B37)*3*150^2)/(R37*$AD$3^2+3*150^2) -> 314.34625 | AE37: =((B37)*3*150^2)/(R37*$AE$3^2+3*150^2) -> 281.92182 | AF37: =((B37)*3*150^2)/(R37*$AF$3^2+3*150^2) -> 228.81692 | AG37: =((B37)*3*150^2)/(R37*$AG$3^2+3*150^2) -> 181.06695 | AH37: =((B37)*3*150^2)/(R37*$AH$3^2+3*150^2) -> 113.43381 | AI37: =((B37)*3*150^2)/(R37*$AI$3^2+3*150^2) -> 74.483649
A38: 363 | B38: 347.2 | C38: 322.6 | D38: 284.9 | E38: 222.7 | F38: 171.8 | G38: 97.6 | H38: 56.1 | I38: =B38/1000 -> 0.3472 | J38: =LOG10((((3*150*150)*B38)/C38)-((3*150*150))) -> 3.7115745 | K38: =LOG10((((3*150*150)*B38)/D38)-((3*150*150))) -> 4.1690994 | L38: =LOG10((((3*150*150)*B38)/E38)-((3*150*150))) -> 4.5767529 | M38: =LOG10((((3*150*150)*B38)/F38)-((3*150*150))) -> 4.8383102 | N38: =LOG10((((3*150*150)*B38)/G38)-((3*150*150))) -> 5.2370985 | O38: =LOG10((((3*150*150)*B38)/H38)-((3*150*150))) -> 5.5443831 | P38: =10^(INTERCEPT(J38:O38,$J$1:$O$1)) -> 0.0249622 | Q38: =LINEST(J38:O38,$J$1:$O$1) -> 2.3206097 | R38: =ROUND(10^((SUM(J38:N38)-2*SUM($J$1:$N$1))/5),3) -> 0.174 | S38: =ROUND(-1.5*((150^2)/(R38*I38))/1000,0) -> -559 | T38: =-4*S38 -> 2236 | U38: =ROUND(150/(R38^0.5),0) -> 360 | V38: =ROUND(150*I38*ATAN((1800*SQRT(3*R38))/(3*150))*SQRT(3/(R38)),0) -> 268 | W38: =ROUND(1/SQRT(R38),3) -> 2.397 | Y38: =ROUND(B38-D38,3) -> 62.3 | Z38: =ROUND(D38-F38,3) -> 113.1 | AA38: =ROUND(F38-G38,3) -> 74.2 | AC38: =((B38)*3*150^2)/(R38*$AC$3^2+3*150^2) -> 347.2 | AD38: =((B38)*3*150^2)/(R38*$AD$3^2+3*150^2) -> 314.74617 | AE38: =((B38)*3*150^2)/(R38*$AE$3^2+3*150^2) -> 281.81818 | AF38: =((B38)*3*150^2)/(R38*$AF$3^2+3*150^2) -> 228.12089 | AG38: =((B38)*3*150^2)/(R38*$AG$3^2+3*150^2) -> 180.08299 | AH38: =((B38)*3*150^2)/(R38*$AH$3^2+3*150^2) -> 112.43523 | AI38: =((B38)*3*150^2)/(R38*$AI$3^2+3*150^2) -> 73.684211
A39: 692 | B39: 606.1 | C39: 565.6 | D39: 501.7 | E39: 397.7 | F39: 309.7 | G39: 182.2 | H39: 107.5 | I39: =B39/1000 -> 0.6061 | J39: =LOG10((((3*150*150)*B39)/C39)-((3*150*150))) -> 3.6842494 | K39: =LOG10((((3*150*150)*B39)/D39)-((3*150*150))) -> 4.1475602 | L39: =LOG10((((3*150*150)*B39)/E39)-((3*150*150))) -> 4.5486459 | M39: =LOG10((((3*150*150)*B39)/F39)-((3*150*150))) -> 4.8102408 | N39: =LOG10((((3*150*150)*B39)/G39)-((3*150*150))) -> 5.1960188 | O39: =LOG10((((3*150*150)*B39)/H39)-((3*150*150))) -> 5.4956476 | P39: =10^(INTERCEPT(J39:O39,$J$1:$O$1)) -> 0.027905395 | Q39: =LINEST(J39:O39,$J$1:$O$1) -> 2.2907329 | R39: =ROUND(10^((SUM(J39:N39)-2*SUM($J$1:$N$1))/5),3) -> 0.163 | S39: =ROUND(-1.5*((150^2)/(R39*I39))/1000,0) -> -342 | T39: =-4*S39 -> 1368 | U39: =ROUND(150/(R39^0.5),0) -> 372 | V39: =ROUND(150*I39*ATAN((1800*SQRT(3*R39))/(3*150))*SQRT(3/(R39)),0) -> 479 | W39: =ROUND(1/SQRT(R39),3) -> 2.477 | Y39: =ROUND(B39-D39,3) -> 104.4 | Z39: =ROUND(D39-F39,3) -> 192 | AA39: =ROUND(F39-G39,3) -> 127.5 | AC39: =((B39)*3*150^2)/(R39*$AC$3^2+3*150^2) -> 606.1 | AD39: =((B39)*3*150^2)/(R39*$AD$3^2+3*150^2) -> 552.7121 | AE39: =((B39)*3*150^2)/(R39*$AE$3^2+3*150^2) -> 497.89157 | AF39: =((B39)*3*150^2)/(R39*$AF$3^2+3*150^2) -> 407.05171 | AG39: =((B39)*3*150^2)/(R39*$AG$3^2+3*150^2) -> 324.23324 | AH39: =((B39)*3*150^2)/(R39*$AH$3^2+3*150^2) -> 205.0406 | AI39: =((B39)*3*150^2)/(R39*$AI$3^2+3*150^2) -> 135.37076
A40: 719 | B40: 614.5 | C40: 572.5 | D40: 509 | E40: 405.1 | F40: 315.8 | G40: 187.3 | H40: 111 | I40: =B40/1000 -> 0.6145 | J40: =LOG10((((3*150*150)*B40)/C40)-((3*150*150))) -> 3.6947776 | K40: =LOG10((((3*150*150)*B40)/D40)-((3*150*150))) -> 4.1458385 | L40: =LOG10((((3*150*150)*B40)/E40)-((3*150*150))) -> 4.5427182 | M40: =LOG10((((3*150*150)*B40)/F40)-((3*150*150))) -> 4.8051269 | N40: =LOG10((((3*150*150)*B40)/G40)-((3*150*150))) -> 5.1873972 | O40: =LOG10((((3*150*150)*B40)/H40)-((3*150*150))) -> 5.4859803 | P40: =10^(INTERCEPT(J40:O40,$J$1:$O$1)) -> 0.031893114 | Q40: =LINEST(J40:O40,$J$1:$O$1) -> 2.2680414 | R40: =ROUND(10^((SUM(J40:N40)-2*SUM($J$1:$N$1))/5),3) -> 0.162 | S40: =ROUND(-1.5*((150^2)/(R40*I40))/1000,0) -> -339 | T40: =-4*S40 -> 1356 | U40: =ROUND(150/(R40^0.5),0) -> 373 | V40: =ROUND(150*I40*ATAN((1800*SQRT(3*R40))/(3*150))*SQRT(3/(R40)),0) -> 486 | W40: =ROUND(1/SQRT(R40),3) -> 2.485 | Y40: =ROUND(B40-D40,3) -> 105.5 | Z40: =ROUND(D40-F40,3) -> 193.2 | AA40: =ROUND(F40-G40,3) -> 128.5 | AC40: =((B40)*3*150^2)/(R40*$AC$3^2+3*150^2) -> 614.5 | AD40: =((B40)*3*150^2)/(R40*$AD$3^2+3*150^2) -> 560.67518 | AE40: =((B40)*3*150^2)/(R40*$AE$3^2+3*150^2) -> 505.34539 | AF40: =((B40)*3*150^2)/(R40*$AF$3^2+3*150^2) -> 413.52624 | AG40: =((B40)*3*150^2)/(R40*$AG$3^2+3*150^2) -> 329.66738 | AH40: =((B40)*3*150^2)/(R40*$AH$3^2+3*150^2) -> 208.72962 | AI40: =((B40)*3*150^2)/(R40*$AI$3^2+3*150^2) -> 137.90395
A41: 711 | B41: 603.4 | C41: 562.3 | D41: 499.8 | E41: 398 | F41: 310.5 | G41: 184.1 | H41: 109.3 | I41: =B41/1000 -> 0.6034 | J41: =LOG10((((3*150*150)*B41)/C41)-((3*150*150))) -> 3.6931775 | K41: =LOG10((((3*150*150)*B41)/D41)-((3*150*150))) -> 4.1458673 | L41: =LOG10((((3*150*150)*B41)/E41)-((3*150*150))) -> 4.5420211 | M41: =LOG10((((3*150*150)*B41)/F41)-((3*150*150))) -> 4.8039615 | N41: =LOG10((((3*150*150)*B41)/G41)-((3*150*150))) -> 5.1867748 | O41: =LOG10((((3*150*150)*B41)/H41)-((3*150*150))) -> 5.4844985 | P41: =10^(INTERCEPT(J41:O41,$J$1:$O$1)) -> 0.031875354 | Q41: =LINEST(J41:O41,$J$1:$O$1) -> 2.2677898 | R41: =ROUND(10^((SUM(J41:N41)-2*SUM($J$1:$N$1))/5),3) -> 0.162 | S41: =ROUND(-1.5*((150^2)/(R41*I41))/1000,0) -> -345 | T41: =-4*S41 -> 1380 | U41: =ROUND(150/(R41^0.5),0) -> 373 | V41: =ROUND(150*I41*ATAN((1800*SQRT(3*R41))/(3*150))*SQRT(3/(R41)),0) -> 478 | W41: =ROUND(1/SQRT(R41),3) -> 2.485 | Y41: =ROUND(B41-D41,3) -> 103.6 | Z41: =ROUND(D41-F41,3) -> 189.3 | AA41: =ROUND(F41-G41,3) -> 126.4 | AC41: =((B41)*3*150^2)/(R41*$AC$3^2+3*150^2) -> 603.4 | AD41: =((B41)*3*150^2)/(R41*$AD$3^2+3*150^2) -> 550.54745 | AE41: =((B41)*3*150^2)/(R41*$AE$3^2+3*150^2) -> 496.21711 | AF41: =((B41)*3*150^2)/(R41*$AF$3^2+3*150^2) -> 406.05653 | AG41: =((B41)*3*150^2)/(R41*$AG$3^2+3*150^2) -> 323.71245 | AH41: =((B41)*3*150^2)/(R41*$AH$3^2+3*150^2) -> 204.95924 | AI41: =((B41)*3*150^2)/(R41*$AI$3^2+3*150^2) -> 135.41293
...

Sheet paraméter számoló (3)
B1: 0 | C1: 200 | D1: 300 | E1: 450 | F1: 600 | G1: 900 | H1: 1200 | I1: 0 | J1: =LOG10(C1) -> 2.30103 | K1: =LOG10(D1) -> 2.4771213 | L1: =LOG10(E1) -> 2.6532125 | M1: =LOG10(F1) -> 2.7781513 | N1: =LOG10(G1) -> 2.9542425 | O1: =LOG10(H1) -> 3.0791812
B2: D1 | C2: D2 | D2: D3 | E2: D4 | F2: D5 | G2: D6 | H2: D7 | I2: D1 | J2: D2 | K2: D3 | L2: D4 | M2: D5 | N2: D6 | O2: D7 | P2: α | Q2: β | R2: c | S2: R0 (m) | T2: R1 (m) | U2: L (mm) | V2: T (mm2) | W2: l | Y2: SCI | Z2: BDI | AA2: BCI | AC2: D1 | AD2: D2 | AE2: D3 | AF2: D4 | AG2: D5 | AH2: D6 | AI2: D7
B3: 0 | C3: 200 | D3: 300 | E3: 450 | F3: 600 | G3: 900 | H3: 1200 | AC3: 0 | AD3: 200 | AE3: 300 | AF3: 450 | AG3: 600 | AH3: 900 | AI3: 1200
A4: 378 | B4: 213.8 | C4: 186.4 | D4: 167.8 | E4: 136.2 | F4: 115.7 | G4: 72.7 | H4: 45.2 | I4: =B4/1000 -> 0.2138 | J4: =LOG10((((3*150*150)*B4)/C4)-((3*150*150))) -> 3.9966084 | K4: =LOG10((((3*150*150)*B4)/D4)-((3*150*150))) -> 4.2672696 | L4: =LOG10((((3*150*150)*B4)/E4)-((3*150*150))) -> 4.5849884 | M4: =LOG10((((3*150*150)*B4)/F4)-((3*150*150))) -> 4.7576394 | N4: =LOG10((((3*150*150)*B4)/G4)-((3*150*150))) -> 5.1172964 | O4: =LOG10((((3*150*150)*B4)/H4)-((3*150*150))) -> 5.4010229 | P4: =10^(INTERCEPT(J4:O4,$J$1:$O$1)) -> 0.71307304 | Q4: =LINEST(J4:O4,$J$1:$O$1) -> 1.7857619 | R4: =ROUND(10^((SUM(J4:N4)-2*SUM($J$1:$N$1))/5),3) -> 0.19 | S4: =ROUND(-1.5*((150^2)/(R4*I4))/1000,0) -> -831 | T4: =-4*S4 -> 3324 | U4: =ROUND(150/(R4^0.5),0) -> 344 | V4: =ROUND(150*I4*ATAN((1800*SQRT(3*R4))/(3*150))*SQRT(3/(R4)),0) -> 159 | W4: =ROUND(1/SQRT(R4),3) -> 2.294 | X4: =SLOPE(W4:W15,A4:A15) -> 0.00014753156 | Y4: =ROUND(B4-D4,3) -> 46 | Z4: =ROUND(D4-F4,3) -> 52.1 | AA4: =ROUND(F4-G4,3) -> 43 | AC4: =((B4)*3*150^2)/(R4*$AC$3^2+3*150^2) -> 213.8 | AD4: =((B4)*3*150^2)/(R4*$AD$3^2+3*150^2) -> 192.16378 | AE4: =((B4)*3*150^2)/(R4*$AE$3^2+3*150^2) -> 170.58511 | AF4: =((B4)*3*150^2)/(R4*$AF$3^2+3*150^2) -> 136.17834 | AG4: =((B4)*3*150^2)/(R4*$AG$3^2+3*150^2) -> 106.19205 | AH4: =((B4)*3*150^2)/(R4*$AH$3^2+3*150^2) -> 65.182927 | AI4: =((B4)*3*150^2)/(R4*$AI$3^2+3*150^2) -> 42.308707 | AJ4: =ROUND((-0.07/(2*S4))*1000000,0) -> 42
A5: 380 | B5: 201.6 | C5: 175.2 | D5: 156.7 | E5: 127.5 | F5: 108.1 | G5: 68.1 | H5: 41.6 | I5: =B5/1000 -> 0.2016 | J5: =LOG10((((3*150*150)*B5)/C5)-((3*150*150))) -> 4.0073736 | K5: =LOG10((((3*150*150)*B5)/D5)-((3*150*150))) -> 4.2864811 | L5: =LOG10((((3*150*150)*B5)/E5)-((3*150*150))) -> 4.5936118 | M5: =LOG10((((3*150*150)*B5)/F5)-((3*150*150))) -> 4.7662897 | N5: =LOG10((((3*150*150)*B5)/G5)-((3*150*150))) -> 5.1216379 | O5: =LOG10((((3*150*150)*B5)/H5)-((3*150*150))) -> 5.4143304 | P5: =10^(INTERCEPT(J5:O5,$J$1:$O$1)) -> 0.75966553 | Q5: =LINEST(J5:O5,$J$1:$O$1) -> 1.7796035 | R5: =ROUND(10^((SUM(J5:N5)-2*SUM($J$1:$N$1))/5),3) -> 0.195 | S5: =ROUND(-1.5*((150^2)/(R5*I5))/1000,0) -> -859 | T5: =-4*S5 -> 3436 | U5: =ROUND(150/(R5^0.5),0) -> 340 | V5: =ROUND(150*I5*ATAN((1800*SQRT(3*R5))/(3*150))*SQRT(3/(R5)),0) -> 149 | W5: =ROUND(1/SQRT(R5),3) -> 2.265 | Y5: =ROUND(B5-D5,3) -> 44.9 | Z5: =ROUND(D5-F5,3) -> 48.6 | AA5: =ROUND(F5-G5,3) -> 40 | AC5: =((B5)*3*150^2)/(R5*$AC$3^2+3*150^2) -> 201.6 | AD5: =((B5)*3*150^2)/(R5*$AD$3^2+3*150^2) -> 180.71713 | AE5: =((B5)*3*150^2)/(R5*$AE$3^2+3*150^2) -> 160 | AF5: =((B5)*3*150^2)/(R5*$AF$3^2+3*150^2) -> 127.19243 | AG5: =((B5)*3*150^2)/(R5*$AG$3^2+3*150^2) -> 98.823529 | AH5: =((B5)*3*150^2)/(R5*$AH$3^2+3*150^2) -> 60.359281 | AI5: =((B5)*3*150^2)/(R5*$AI$3^2+3*150^2) -> 39.069767 | AJ5: =ROUND((-0.07/(2*S5))*1000000,0) -> 41
A6: 383 | B6: 199.6 | C6: 173.1 | D6: 155 | E6: 125.7 | F6: 107.1 | G6: 67.1 | H6: 40.8 | I6: =B6/1000 -> 0.1996 | J6: =LOG10((((3*150*150)*B6)/C6)-((3*150*150))) -> 4.0142526 | K6: =LOG10((((3*150*150)*B6)/D6)-((3*150*150))) -> 4.2883069 | L6: =LOG10((((3*150*150)*B6)/E6)-((3*150*150))) -> 4.5986129 | M6: =LOG10((((3*150*150)*B6)/F6)-((3*150*150))) -> 4.765656 | N6: =LOG10((((3*150*150)*B6)/G6)-((3*150*150))) -> 5.1247971 | O6: =LOG10((((3*150*150)*B6)/H6)-((3*150*150))) -> 5.4194941 | P6: =10^(INTERCEPT(J6:O6,$J$1:$O$1)) -> 0.7752686 | Q6: =LINEST(J6:O6,$J$1:$O$1) -> 1.777659 | R6: =ROUND(10^((SUM(J6:N6)-2*SUM($J$1:$N$1))/5),3) -> 0.196 | S6: =ROUND(-1.5*((150^2)/(R6*I6))/1000,0) -> -863 | T6: =-4*S6 -> 3452 | U6: =ROUND(150/(R6^0.5),0) -> 339 | V6: =ROUND(150*I6*ATAN((1800*SQRT(3*R6))/(3*150))*SQRT(3/(R6)),0) -> 147 | W6: =ROUND(1/SQRT(R6),3) -> 2.259 | Y6: =ROUND(B6-D6,3) -> 44.6 | Z6: =ROUND(D6-F6,3) -> 47.9 | AA6: =ROUND(F6-G6,3) -> 40 | AC6: =((B6)*3*150^2)/(R6*$AC$3^2+3*150^2) -> 199.6 | AD6: =((B6)*3*150^2)/(R6*$AD$3^2+3*150^2) -> 178.82931 | AE6: =((B6)*3*150^2)/(R6*$AE$3^2+3*150^2) -> 158.24524 | AF6: =((B6)*3*150^2)/(R6*$AF$3^2+3*150^2) -> 125.6927 | AG6: =((B6)*3*150^2)/(R6*$AG$3^2+3*150^2) -> 97.588005 | AH6: =((B6)*3*150^2)/(R6*$AH$3^2+3*150^2) -> 59.546539 | AI6: =((B6)*3*150^2)/(R6*$AI$3^2+3*150^2) -> 38.522903 | AJ6: =ROUND((-0.07/(2*S6))*1000000,0) -> 41
A7: 383 | B7: 197.5 | C7: 171.5 | D7: 153.7 | E7: 125 | F7: 106.7 | G7: 67 | H7: 40.8 | I7: =B7/1000 -> 0.1975 | J7: =LOG10((((3*150*150)*B7)/C7)-((3*150*150))) -> 4.010013 | K7: =LOG10((((3*150*150)*B7)/D7)-((3*150*150))) -> 4.284104 | L7: =LOG10((((3*150*150)*B7)/E7)-((3*150*150))) -> 4.5927318 | M7: =LOG10((((3*150*150)*B7)/F7)-((3*150*150))) -> 4.7592252 | N7: =LOG10((((3*150*150)*B7)/G7)-((3*150*150))) -> 5.1188395 | O7: =LOG10((((3*150*150)*B7)/H7)-((3*150*150))) -> 5.4137126 | P7: =10^(INTERCEPT(J7:O7,$J$1:$O$1)) -> 0.7778054 | Q7: =LINEST(J7:O7,$J$1:$O$1) -> 1.7751345 | R7: =ROUND(10^((SUM(J7:N7)-2*SUM($J$1:$N$1))/5),3) -> 0.194 | S7: =ROUND(-1.5*((150^2)/(R7*I7))/1000,0) -> -881 | T7: =-4*S7 -> 3524 | U7: =ROUND(150/(R7^0.5),0) -> 341 | V7: =ROUND(150*I7*ATAN((1800*SQRT(3*R7))/(3*150))*SQRT(3/(R7)),0) -> 146 | W7: =ROUND(1/SQRT(R7),3) -> 2.27 | Y7: =ROUND(B7-D7,3) -> 43.8 | Z7: =ROUND(D7-F7,3) -> 47 | AA7: =ROUND(F7-G7,3) -> 39.7 | AC7: =((B7)*3*150^2)/(R7*$AC$3^2+3*150^2) -> 197.5 | AD7: =((B7)*3*150^2)/(R7*$AD$3^2+3*150^2) -> 177.13593 | AE7: =((B7)*3*150^2)/(R7*$AE$3^2+3*150^2) -> 156.91208 | AF7: =((B7)*3*150^2)/(R7*$AF$3^2+3*150^2) -> 124.84197 | AG7: =((B7)*3*150^2)/(R7*$AG$3^2+3*150^2) -> 97.067497 | AH7: =((B7)*3*150^2)/(R7*$AH$3^2+3*150^2) -> 59.344952 | AI7: =((B7)*3*150^2)/(R7*$AI$3^2+3*150^2) -> 38.434094 | AJ7: =ROUND((-0.07/(2*S7))*1000000,0) -> 40
A8: 724 | B8: 363 | C8: 319.2 | D8: 287 | E8: 240.5 | F8: 200.4 | G8: 134.5 | H8: 87.7 | I8: =B8/1000 -> 0.363 | J8: =LOG10((((3*150*150)*B8)/C8)-((3*150*150))) -> 3.966715 | K8: =LOG10((((3*150*150)*B8)/D8)-((3*150*150))) -> 4.2522355 | L8: =LOG10((((3*150*150)*B8)/E8)-((3*150*150))) -> 4.5363248 | M8: =LOG10((((3*150*150)*B8)/F8)-((3*150*150))) -> 4.7385266 | N8: =LOG10((((3*150*150)*B8)/G8)-((3*150*150))) -> 5.0594677 | O8: =LOG10((((3*150*150)*B8)/H8)-((3*150*150))) -> 5.3261104 | P8: =10^(INTERCEPT(J8:O8,$J$1:$O$1)) -> 0.94021169 | Q8: =LINEST(J8:O8,$J$1:$O$1) -> 1.7262902 | R8: =ROUND(10^((SUM(J8:N8)-2*SUM($J$1:$N$1))/5),3) -> 0.176 | S8: =ROUND(-1.5*((150^2)/(R8*I8))/1000,0) -> -528 | T8: =-4*S8 -> 2112 | U8: =ROUND(150/(R8^0.5),0) -> 358 | V8: =ROUND(150*I8*ATAN((1800*SQRT(3*R8))/(3*150))*SQRT(3/(R8)),0) -> 279 | W8: =ROUND(1/SQRT(R8),3) -> 2.384 | Y8: =ROUND(B8-D8,3) -> 76 | Z8: =ROUND(D8-F8,3) -> 86.6 | AA8: =ROUND(F8-G8,3) -> 65.9 | AC8: =((B8)*3*150^2)/(R8*$AC$3^2+3*150^2) -> 363 | AD8: =((B8)*3*150^2)/(R8*$AD$3^2+3*150^2) -> 328.71613 | AE8: =((B8)*3*150^2)/(R8*$AE$3^2+3*150^2) -> 294.00648 | AF8: =((B8)*3*150^2)/(R8*$AF$3^2+3*150^2) -> 237.56545 | AG8: =((B8)*3*150^2)/(R8*$AG$3^2+3*150^2) -> 187.24209 | AH8: =((B8)*3*150^2)/(R8*$AH$3^2+3*150^2) -> 116.64524 | AI8: =((B8)*3*150^2)/(R8*$AI$3^2+3*150^2) -> 76.346046 | AJ8: =ROUND((-0.07/(2*S8))*1000000,0) -> 66
